Workbook

Sheet Boletins Nuppa Site
A1: blt_numero | B1: blt_ano | C1: blt_data_lev | D1: Grupo | E1: Produto | F1: Unidade | G1: Comum | H1: Mínimo | I1: Máximo | J1: Média | K1: Mediana | L1: >MAX | M1: >MED | N1: MAX < MED | O1: observações
A2: 37 | B2: 2023 | C2: 44931 | D2: GRUPO A - Verduras (Folhosas, Flores e Hastes) | E2: Acelga | F2: 12 unidades | H2: 32 | I2: 32 | J2: 32 | K2: 32 | L2: =IF(H2>I2,"ERRO","OK") -> OK | M2: =IF(H2>J2,"ERRO","OK") -> OK | N2: =IF(I2<J2,"ERRO","OK") -> OK
A3: 37 | B3: 2023 | C3: 44931 | D3: GRUPO A - Verduras (Folhosas, Flores e Hastes) | E3: Agrião | F3: 12 unidades | H3: 60 | I3: 60 | J3: 60 | K3: 60 | L3: =IF(H3>I3,"ERRO","OK") -> OK | M3: =IF(H3>J3,"ERRO","OK") -> OK | N3: =IF(I3<J3,"ERRO","OK") -> OK
A4: 37 | B4: 2023 | C4: 44931 | D4: GRUPO A - Verduras (Folhosas, Flores e Hastes) | E4: Alface Americana | F4: 12 unidades | H4: 24 | I4: 36 | J4: 30 | K4: 30 | L4: =IF(H4>I4,"ERRO","OK") -> OK | M4: =IF(H4>J4,"ERRO","OK") -> OK | N4: =IF(I4<J4,"ERRO","OK") -> OK
A5: 37 | B5: 2023 | C5: 44931 | D5: GRUPO A - Verduras (Folhosas, Flores e Hastes) | E5: Alface crespa | F5: 12 unidades | H5: 18 | I5: 30 | J5: 24 | K5: 24 | L5: =IF(H5>I5,"ERRO","OK") -> OK | M5: =IF(H5>J5,"ERRO","OK") -> OK | N5: =IF(I5<J5,"ERRO","OK") -> OK
A6: 37 | B6: 2023 | C6: 44931 | D6: GRUPO A - Verduras (Folhosas, Flores e Hastes) | E6: Alface lisa | F6: 12 unidades | H6: 18 | I6: 30 | J6: 24 | K6: 24 | L6: =IF(H6>I6,"ERRO","OK") -> OK | M6: =IF(H6>J6,"ERRO","OK") -> OK | N6: =IF(I6<J6,"ERRO","OK") -> OK
A7: 37 | B7: 2023 | C7: 44931 | D7: GRUPO A - Verduras (Folhosas, Flores e Hastes) | E7: Almeirão | F7: 12 unidades | H7: 48 | I7: 48 | J7: 48 | K7: 48 | L7: =IF(H7>I7,"ERRO","OK") -> OK | M7: =IF(H7>J7,"ERRO","OK") -> OK | N7: =IF(I7<J7,"ERRO","OK") -> OK
A8: 37 | B8: 2023 | C8: 44931 | D8: GRUPO A - Verduras (Folhosas, Flores e Hastes) | E8: Brócolos ninja/japonês | F8: 12 unidades | H8: 60 | I8: 60 | J8: 60 | K8: 60 | L8: =IF(H8>I8,"ERRO","OK") -> OK | M8: =IF(H8>J8,"ERRO","OK") -> OK | N8: =IF(I8<J8,"ERRO","OK") -> OK
A9: 37 | B9: 2023 | C9: 44931 | D9: GRUPO A - Verduras (Folhosas, Flores e Hastes) | E9: Brócolos ramoso | F9: 12 unidades | G9: 48 | H9: 48 | I9: 60 | J9: 52 | K9: 48 | L9: =IF(H9>I9,"ERRO","OK") -> OK | M9: =IF(H9>J9,"ERRO","OK") -> OK | N9: =IF(I9<J9,"ERRO","OK") -> OK
A10: 37 | B10: 2023 | C10: 44931 | D10: GRUPO A - Verduras (Folhosas, Flores e Hastes) | E10: Couve-Manteiga | F10: 12 unidades | G10: 15 | H10: 15 | I10: 24 | J10: 18 | K10: 15 | L10: =IF(H10>I10,"ERRO","OK") -> OK | M10: =IF(H10>J10,"ERRO","OK") -> OK | N10: =IF(I10<J10,"ERRO","OK") -> OK
A11: 37 | B11: 2023 | C11: 44931 | D11: GRUPO A - Verduras (Folhosas, Flores e Hastes) | E11: Couve | H11: 60 | I11: 60 | J11: 60 | K11: 60 | L11: =IF(H11>I11,"ERRO","OK") -> OK | M11: =IF(H11>J11,"ERRO","OK") -> OK | N11: =IF(I11<J11,"ERRO","OK") -> OK
A12: 37 | B12: 2023 | C12: 44931 | D12: GRUPO A - Verduras (Folhosas, Flores e Hastes) | E12: Escarola | F12: 12 unidades | H12: 18 | I12: 30 | J12: 24 | K12: 24 | L12: =IF(H12>I12,"ERRO","OK") -> OK | M12: =IF(H12>J12,"ERRO","OK") -> OK | N12: =IF(I12<J12,"ERRO","OK") -> OK
A13: 37 | B13: 2023 | C13: 44931 | D13: GRUPO A - Verduras (Folhosas, Flores e Hastes) | E13: Espinafre | F13: 12 unidades | H13: 42 | I13: 54 | J13: 48 | K13: 48 | L13: =IF(H13>I13,"ERRO","OK") -> OK | M13: =IF(H13>J13,"ERRO","OK") -> OK | N13: =IF(I13<J13,"ERRO","OK") -> OK
A14: 37 | B14: 2023 | C14: 44931 | D14: GRUPO A - Verduras (Folhosas, Flores e Hastes) | E14: Rabanete | F14: 12 maços | H14: 36 | I14: 48 | J14: 42 | K14: 42 | L14: =IF(H14>I14,"ERRO","OK") -> OK | M14: =IF(H14>J14,"ERRO","OK") -> OK | N14: =IF(I14<J14,"ERRO","OK") -> OK
A15: 37 | B15: 2023 | C15: 44931 | D15: GRUPO A - Verduras (Folhosas, Flores e Hastes) | E15: Repolho roxo | F15: 12 unidades | H15: 60 | I15: 60 | J15: 60 | K15: 60 | L15: =IF(H15>I15,"ERRO","OK") -> OK | M15: =IF(H15>J15,"ERRO","OK") -> OK | N15: =IF(I15<J15,"ERRO","OK") -> OK
A16: 37 | B16: 2023 | C16: 44931 | D16: GRUPO A - Verduras (Folhosas, Flores e Hastes) | E16: Repolho Verde | F16: 12 unidades | H16: 24 | I16: 36 | J16: 30 | K16: 30 | L16: =IF(H16>I16,"ERRO","OK") -> OK | M16: =IF(H16>J16,"ERRO","OK") -> OK | N16: =IF(I16<J16,"ERRO","OK") -> OK
A17: 37 | B17: 2023 | C17: 44931 | D17: GRUPO A - Verduras (Folhosas, Flores e Hastes) | E17: Rúcula | F17: 12 unidades | G17: 42 | H17: 36 | I17: 42 | J17: 40 | K17: 42 | L17: =IF(H17>I17,"ERRO","OK") -> OK | M17: =IF(H17>J17,"ERRO","OK") -> OK | N17: =IF(I17<J17,"ERRO","OK") -> OK
A18: 37 | B18: 2023 | C18: 44931 | D18: GRUPO B - Hortaliças Condimentares (Temperos) | E18: Cebolinha | F18: Maço 0,5 kg | G18: 4 | H18: 3 | I18: 4 | J18: 3.67 | K18: 4 | L18: =IF(H18>I18,"ERRO","OK") -> OK | M18: =IF(H18>J18,"ERRO","OK") -> OK | N18: =IF(I18<J18,"ERRO","OK") -> ERRO
A19: 37 | B19: 2023 | C19: 44931 | D19: GRUPO B - Hortaliças Condimentares (Temperos) | E19: Coentro | F19: Maço 2 kg | G19: 25 | H19: 25 | I19: 25 | J19: 25 | K19: 25 | L19: =IF(H19>I19,"ERRO","OK") -> OK | M19: =IF(H19>J19,"ERRO","OK") -> OK | N19: =IF(I19<J19,"ERRO","OK") -> OK
A20: 37 | B20: 2023 | C20: 44931 | D20: GRUPO B - Hortaliças Condimentares (Temperos) | E20: Salsinha | F20: Maço 2 kg | G20: 25 | H20: 20 | I20: 25 | J20: 22.5 | K20: 22.5 | L20: =IF(H20>I20,"ERRO","OK") -> OK | M20: =IF(H20>J20,"ERRO","OK") -> OK | N20: =IF(I20<J20,"ERRO","OK") -> ERRO
A21: 37 | B21: 2023 | C21: 44931 | D21: GRUPO C - Hortaliças Legumes (Leguminosas (Vagens), Frutos, Raízes Tuberosas, Tubérculos e Bulbos) | E21: Abobrinha Italiana | F21: 17 kg | G21: 60 | H21: 50 | I21: 60 | J21: 57.5 | K21: 60 | L21: =IF(H21>I21,"ERRO","OK") -> OK | M21: =IF(H21>J21,"ERRO","OK") -> OK | N21: =IF(I21<J21,"ERRO","OK") -> ERRO
A22: 37 | B22: 2023 | C22: 44931 | D22: GRUPO C - Hortaliças Legumes (Leguminosas (Vagens), Frutos, Raízes Tuberosas, Tubérculos e Bulbos) | E22: Batata-doce | F22: 18 kg | G22: 50 | H22: 50 | I22: 65 | J22: 55 | K22: 50 | L22: =IF(H22>I22,"ERRO","OK") -> OK | M22: =IF(H22>J22,"ERRO","OK") -> OK | N22: =IF(I22<J22,"ERRO","OK") -> OK
A23: 37 | B23: 2023 | C23: 44931 | D23: GRUPO C - Hortaliças Legumes (Leguminosas (Vagens), Frutos, Raízes Tuberosas, Tubérculos e Bulbos) | E23: Berinjela comum | F23: 10 kg | G23: 40 | H23: 40 | I23: 50 | J23: 44.17 | K23: 42.5 | L23: =IF(H23>I23,"ERRO","OK") -> OK | M23: =IF(H23>J23,"ERRO","OK") -> OK | N23: =IF(I23<J23,"ERRO","OK") -> ERRO
A24: 37 | B24: 2023 | C24: 44931 | D24: GRUPO C - Hortaliças Legumes (Leguminosas (Vagens), Frutos, Raízes Tuberosas, Tubérculos e Bulbos) | E24: Berinjela japonesa | F24: 10 kg | L24: =IF(H24>I24,"ERRO","OK") -> OK | M24: =IF(H24>J24,"ERRO","OK") -> OK | N24: =IF(I24<J24,"ERRO","OK") -> OK
A25: 37 | B25: 2023 | C25: 44931 | D25: GRUPO C - Hortaliças Legumes (Leguminosas (Vagens), Frutos, Raízes Tuberosas, Tubérculos e Bulbos) | E25: Beterraba | F25: 20 kg | H25: 48 | I25: 60 | J25: 52.67 | K25: 50 | L25: =IF(H25>I25,"ERRO","OK") -> OK | M25: =IF(H25>J25,"ERRO","OK") -> OK | N25: =IF(I25<J25,"ERRO","OK") -> ERRO
A26: 37 | B26: 2023 | C26: 44931 | D26: GRUPO C - Hortaliças Legumes (Leguminosas (Vagens), Frutos, Raízes Tuberosas, Tubérculos e Bulbos) | E26: Cenoura | F26: 18 kg | G26: 55 | H26: 50 | I26: 60 | J26: 55 | K26: 55 | L26: =IF(H26>I26,"ERRO","OK") -> OK | M26: =IF(H26>J26,"ERRO","OK") -> OK | N26: =IF(I26<J26,"ERRO","OK") -> OK
A27: 37 | B27: 2023 | C27: 44931 | D27: GRUPO C - Hortaliças Legumes (Leguminosas (Vagens), Frutos, Raízes Tuberosas, Tubérculos e Bulbos) | E27: Chuchu | F27: 18 kg | G27: 40 | H27: 30 | I27: 50 | J27: 40 | K27: 40 | L27: =IF(H27>I27,"ERRO","OK") -> OK | M27: =IF(H27>J27,"ERRO","OK") -> OK | N27: =IF(I27<J27,"ERRO","OK") -> OK
A28: 37 | B28: 2023 | C28: 44931 | D28: GRUPO C - Hortaliças Legumes (Leguminosas (Vagens), Frutos, Raízes Tuberosas, Tubérculos e Bulbos) | E28: Jiló | F28: 17 kg | G28: 50 | H28: 50 | I28: 70 | J28: 56.67 | K28: 50 | L28: =IF(H28>I28,"ERRO","OK") -> OK | M28: =IF(H28>J28,"ERRO","OK") -> OK | N28: =IF(I28<J28,"ERRO","OK") -> ERRO
A29: 37 | B29: 2023 | C29: 44931 | D29: GRUPO C - Hortaliças Legumes (Leguminosas (Vagens), Frutos, Raízes Tuberosas, Tubérculos e Bulbos) | E29: Mandioca | F29: 18 kg | L29: =IF(H29>I29,"ERRO","OK") -> OK | M29: =IF(H29>J29,"ERRO","OK") -> OK | N29: =IF(I29<J29,"ERRO","OK") -> OK
A30: 37 | B30: 2023 | C30: 44931 | D30: GRUPO C - Hortaliças Legumes (Leguminosas (Vagens), Frutos, Raízes Tuberosas, Tubérculos e Bulbos) | E30: Pepino comum | F30: 17 kg | G30: 50 | H30: 40 | I30: 60 | J30: 50 | K30: 50 | L30: =IF(H30>I30,"ERRO","OK") -> OK | M30: =IF(H30>J30,"ERRO","OK") -> OK | N30: =IF(I30<J30,"ERRO","OK") -> OK
A31: 37 | B31: 2023 | C31: 44931 | D31: GRUPO C - Hortaliças Legumes (Leguminosas (Vagens), Frutos, Raízes Tuberosas, Tubérculos e Bulbos) | E31: Pepino japonês | F31: 17 kg | G31: 50 | H31: 50 | I31: 60 | J31: 55 | K31: 55 | L31: =IF(H31>I31,"ERRO","OK") -> OK | M31: =IF(H31>J31,"ERRO","OK") -> OK | N31: =IF(I31<J31,"ERRO","OK") -> OK
A32: 37 | B32: 2023 | C32: 44931 | D32: GRUPO C - Hortaliças Legumes (Leguminosas (Vagens), Frutos, Raízes Tuberosas, Tubérculos e Bulbos) | E32: Pimentão verde | F32: 10 kg | H32: 30 | I32: 50 | J32: 40 | K32: 40 | L32: =IF(H32>I32,"ERRO","OK") -> OK | M32: =IF(H32>J32,"ERRO","OK") -> OK | N32: =IF(I32<J32,"ERRO","OK") -> OK
A33: 37 | B33: 2023 | C33: 44931 | D33: GRUPO C - Hortaliças Legumes (Leguminosas (Vagens), Frutos, Raízes Tuberosas, Tubérculos e Bulbos) | E33: Quiabo | F33: 12 kg | G33: 70 | H33: 60 | I33: 80 | J33: 68.33 | K33: 70 | L33: =IF(H33>I33,"ERRO","OK") -> OK | M33: =IF(H33>J33,"ERRO","OK") -> OK | N33: =IF(I33<J33,"ERRO","OK") -> ERRO
A34: 37 | B34: 2023 | C34: 44931 | D34: GRUPO C - Hortaliças Legumes (Leguminosas (Vagens), Frutos, Raízes Tuberosas, Tubérculos e Bulbos) | E34: Tomate Débora | F34: 17 kg | G34: 100 | H34: 90 | I34: 110 | J34: 100 | K34: 100 | L34: =IF(H34>I34,"ERRO","OK") -> OK | M34: =IF(H34>J34,"ERRO","OK") -> OK | N34: =IF(I34<J34,"ERRO","OK") -> OK
A35: 37 | B35: 2023 | C35: 44931 | D35: GRUPO C - Hortaliças Legumes (Leguminosas (Vagens), Frutos, Raízes Tuberosas, Tubérculos e Bulbos) | E35: Vagem macarrão | F35: 17 kg | G35: 80 | H35: 70 | I35: 100 | J35: 83 | K35: 80 | L35: =IF(H35>I35,"ERRO","OK") -> OK | M35: =IF(H35>J35,"ERRO","OK") -> OK | N35: =IF(I35<J35,"ERRO","OK") -> OK
A36: 37 | B36: 2023 | C36: 44931 | D36: GRUPO D - Frutas | E36: Caqui Fuyu | F36: 17 kg | L36: =IF(H36>I36,"ERRO","OK") -> OK | M36: =IF(H36>J36,"ERRO","OK") -> OK | N36: =IF(I36<J36,"ERRO","OK") -> OK
A37: 37 | B37: 2023 | C37: 44931 | D37: GRUPO D - Frutas | E37: Caqui Guimbo | F37: 17 kg | L37: =IF(H37>I37,"ERRO","OK") -> OK | M37: =IF(H37>J37,"ERRO","OK") -> OK | N37: =IF(I37<J37,"ERRO","OK") -> OK
A38: 37 | B38: 2023 | C38: 44931 | D38: GRUPO D - Frutas | E38: Caqui Rama Forte | F38: 17 kg | L38: =IF(H38>I38,"ERRO","OK") -> OK | M38: =IF(H38>J38,"ERRO","OK") -> OK | N38: =IF(I38<J38,"ERRO","OK") -> OK
A39: 37 | B39: 2023 | C39: 44931 | D39: GRUPO D - Frutas | E39: Goiaba | F39: 10 kg | L39: =IF(H39>I39,"ERRO","OK") -> OK | M39: =IF(H39>J39,"ERRO","OK") -> OK | N39: =IF(I39<J39,"ERRO","OK") -> OK
A40: 37 | B40: 2023 | C40: 44931 | D40: GRUPO D - Frutas | E40: Mexerica Polkan | F40: 22 kg | L40: =IF(H40>I40,"ERRO","OK") -> OK | M40: =IF(H40>J40,"ERRO","OK") -> OK | N40: =IF(I40<J40,"ERRO","OK") -> OK
...

Sheet Planilha11
A1: Numero do boletim | B1: Ano do boletim | C1: Produto | D1: Unidade de medida | E1: Comum | F1: Mínimo | G1: Máximo | H1: Média | I1: Mediana
A2: 88 | B2: 2024 | C2: Acelga | D2: 12 unidades | E2: - | F2: 36 | G2: 72 | H2: 54 | I2: 54
A3: 88 | B3: 2024 | C3: Agrião | D3: 12 unidades | E3: 96 | F3: 54 | G3: 96 | H3: 82.5 | I3: 90
A4: 88 | B4: 2024 | C4: Alface Americana | D4: 12 unidades | E4: - | F4: 40 | G4: 60 | H4: 48.25 | I4: 46.5
A5: 88 | B5: 2024 | C5: Alface crespa | D5: 12 unidades | E5: 30 | F5: 25 | G5: 50 | H5: 33.75 | I5: 30
A6: 88 | B6: 2024 | C6: Alface lisa | D6: 12 unidades | E6: 30 | F6: 25 | G6: 50 | H6: 33.75 | I6: 30
A7: 88 | B7: 2024 | C7: Almeirão | D7: 12 unidades | E7: 60 | F7: 60 | G7: 120 | H7: 76.5 | I7: 63
A8: 88 | B8: 2024 | C8: Brócolos ninja/japonês | D8: 12 unidades | E8: 84 | F8: 78 | G8: 84 | H8: 81 | I8: 81
A9: 88 | B9: 2024 | C9: Brócolos ramoso | D9: 12 unidades | E9: 84 | F9: 72 | G9: 96 | H9: 84 | I9: 84
A10: 88 | B10: 2024 | C10: Couve-Manteiga | D10: 12 unidades | E10: 24 | F10: 24 | G10: 30 | H10: 25.5 | I10: 24
A11: 88 | B11: 2024 | C11: Couve-flor | D11: 12 unidades | E11: 96 | F11: 72 | G11: 96 | H11: 87 | I11: 90
A12: 88 | B12: 2024 | C12: Escarola | D12: 12 unidades | E12: 30 | F12: 25 | G12: 36 | H12: 30.25 | I12: 30
A13: 88 | B13: 2024 | C13: Espinafre | D13: 12 unidades | E13: 72 | F13: 60 | G13: 84 | H13: 72 | I13: 72
A14: 88 | B14: 2024 | C14: Rabanete | D14: 12 maços | E14: 72 | F14: 60 | G14: 96 | H14: 75 | I14: 72
A15: 88 | B15: 2024 | C15: Repolho roxo | D15: 12 unidades | E15: 60 | F15: 54 | G15: 72 | H15: 61.5 | I15: 60
A16: 88 | B16: 2024 | C16: Repolho Verde | D16: 12 unidades | E16: 48 | F16: 36 | G16: 48 | H16: 42 | I16: 42
... A23: 88 | B23: 2024 | C23: Batata-doce | D23: 18 kg | E23: 70 | F23: 45 | G23: 70 | H23: 62.5 | I23: 67.5
A24: 88 | B24: 2024 | C24: Berinjela comum | D24: 10 kg | E24: - | F24: 40 | G24: 65 | H24: 53.75 | I24: 55
A25: 88 | B25: 2024 | C25: Berinjela japonesa | D25: 10 kg | E25: - | F25: 65 | G25: 75 | H25: 70 | I25: 70
A26: 88 | B26: 2024 | C26: Beterraba | D26: 20 kg | E26: 60 | F26: 50 | G26: 60 | H26: 55 | I26: 55
A27: 88 | B27: 2024 | C27: Cenoura | D27: 18 kg | E27: - | F27: 60 | G27: 100 | H27: 80 | I27: 80
A28: 88 | B28: 2024 | C28: Chuchu | D28: 18 kg | E28: - | F28: 45 | G28: 90 | H28: 63.75 | I28: 60
A29: 88 | B29: 2024 | C29: Jiló | D29: 17 kg | E29: - | F29: 70 | G29: 100 | H29: 85 | I29: 85
A30: 88 | B30: 2024 | C30: Mandioca | D30: 18 kg | E30: - | F30: 50 | G30: 75 | H30: 62.5 | I30: 62.5
A31: 88 | B31: 2024 | C31: Pepino comum | D31: 17 kg | E31: 80 | F31: 45 | G31: 80 | H31: 68.33 | I31: 80
A32: 88 | B32: 2024 | C32: Pepino japonês | D32: 17 kg | E32: 90 | F32: 80 | G32: 120 | H32: 95 | I32: 90
A33: 88 | B33: 2024 | C33: Pimentão verde | D33: 10 kg | E33: 30 | F33: 20 | G33: 40 | H33: 30 | I33: 30
A34: 88 | B34: 2024 | C34: Quiabo | D34: 12 kg | E34: 90 | F34: 50 | G34: 90 | H34: 78.75 | I34: 87.5
A35: 88 | B35: 2024 | C35: Tomate Débora | D35: 17 kg | E35: - | F35: 60 | G35: 120 | H35: 92.5 | I35: 95
A36: 88 | B36: 2024 | C36: Vagem macarrão | D36: 17 kg | E36: 50 | F36: 50 | G36: 70 | H36: 56.67 | I36: 50
A37: 88 | B37: 2024 | C37: Caqui Fuyu | D37: 10 kg | E37: - | F37: - | G37: - | H37: - | I37: -
A38: 88 | B38: 2024 | C38: Caqui Guimbo | D38: 10 kg | E38: - | F38: - | G38: - | H38: - | I38: -
A39: 88 | B39: 2024 | C39: Caqui Rama Forte | D39: 10 kg | E39: - | F39: - | G39: - | H39: - | I39: -
A40: 88 | B40: 2024 | C40: Goiaba | D40: 10 kg | E40: - | F40: - | G40: - | H40: - | I40: -
A41: 88 | B41: 2024 | C41: Mexerica Polkan | D41: 22 kg | E41: - | F41: - | G41: - | H41: - | I41: -
A42: 85 | B42: 2024 | C42: Acelga | D42: 12 unidades | E42: - | F42: 36 | G42: 72 | H42: 54 | I42: 54
A43: 85 | B43: 2024 | C43: Agrião | D43: 12 unidades | E43: 96 | F43: 54 | G43: 96 | H43: 82.5 | I43: 90
A44: 85 | B44: 2024 | C44: Alface Americana | D44: 12 unidades | E44: - | F44: 40 | G44: 60 | H44: 48.25 | I44: 46.5
A45: 85 | B45: 2024 | C45: Alface crespa | D45: 12 unidades | E45: 30 | F45: 25 | G45: 50 | H45: 33.75 | I45: 30
A46: 85 | B46: 2024 | C46: Alface lisa | D46: 12 unidades | E46: 30 | F46: 25 | G46: 50 | H46: 33.75 | I46: 30
...

Sheet Planilha12
A1: blt_numero | B1: blt_ano | C1: blt_data_lev | D1: grp_nome | E1: Produto | F1: Unidade de medida | G1: Valor mínimo | H1: Valor máximo | I1: Valor médio | J1: Valor comum | K1: Valor mediana
A2: 1 | B2: 2022 | C2: 44644 | D2: Geral | E2: Abobrinha italiana | F2: cx 17 kg | G2: 80 | H2: 120 | I2: 94.29 | J2: 90 | K2: 90
A3: 1 | B3: 2022 | C3: 44644 | D3: Geral | E3: Acelga | F3: cx 12 unid | G3: 35 | H3: 60 | I3: 42.5 | J3: 35 | K3: 50
A4: 1 | B4: 2022 | C4: 44644 | D4: Geral | E4: Agrião | F4: cx 12 unid | G4: 60 | H4: 60 | I4: 60 | J4: 60 | K4: 60
A5: 1 | B5: 2022 | C5: 44644 | D5: Geral | E5: Alface americana | F5: cx 12 unid | G5: 36 | H5: 42 | I5: 39 | J5: 36 | K5: 39
A6: 1 | B6: 2022 | C6: 44644 | D6: Geral | E6: Alface crespa | F6: cx 12 unid | G6: 20 | H6: 30 | I6: 25 | J6: 20 | K6: 25
A7: 1 | B7: 2022 | C7: 44644 | D7: Geral | E7: Alface lisa | F7: cx 12 unid | G7: 30 | H7: 30 | I7: 30 | J7: 30 | K7: 30
A8: 1 | B8: 2022 | C8: 44644 | D8: Geral | E8: Almeirão | F8: cx 12 unid | G8: 36 | H8: 48 | I8: 42 | J8: 36 | K8: 42
A9: 1 | B9: 2022 | C9: 44644 | D9: Geral | E9: Batata-doce | F9: cx 18 kg | G9: 45 | H9: 55 | I9: 51.67 | J9: 55 | K9: 55
A10: 1 | B10: 2022 | C10: 44644 | D10: Geral | E10: Berinjela comum | F10: cx 10 kg | G10: 30 | H10: 50 | I10: 43.29 | J10: 40 | K10: 45
A11: 1 | B11: 2022 | C11: 44644 | D11: Geral | E11: Berinjela japonesa | F11: cx 10 kg | G11: 70 | H11: 80 | I11: 75 | J11: 70 | K11: 75
A12: 1 | B12: 2022 | C12: 44644 | D12: Geral | E12: Beterraba | F12: cx 20 kg | G12: 70 | H12: 85 | I12: 79.17 | J12: 80 | K12: 82.5
A13: 1 | B13: 2022 | C13: 44644 | D13: Geral | E13: Brócolos (ninja ou japonês) | F13: cx 12 unid | G13: 60 | H13: 84 | I13: 72 | J13: 60 | K13: 72
... A40: 2 | B40: 2022 | C40: 44651 | D40: Geral | E40: Abobrinha italiana | F40: cx 17 kg | G40: 60 | H40: 100 | I40: 72.78 | J40: 70 | K40: 70
A41: 2 | B41: 2022 | C41: 44651 | D41: Geral | E41: Acelga | F41: cx 12 unid | G41: 35 | H41: 60 | I41: 47.25 | J41: - | K41: 47
A42: 2 | B42: 2022 | C42: 44651 | D42: Geral | E42: Agrião | F42: cx 12 unid | G42: 50 | H42: 60 | I42: 56.67 | J42: 60 | K42: 60
A43: 2 | B43: 2022 | C43: 44651 | D43: Geral | E43: Alface americana | F43: cx 12 unid | G43: 40 | H43: 42 | I43: 41.33 | J43: 42 | K43: 42
A44: 2 | B44: 2022 | C44: 44651 | D44: Geral | E44: Alface crespa | F44: cx 12 unid | G44: 25 | H44: 30 | I44: 28.33 | J44: 30 | K44: 30
A45: 2 | B45: 2022 | C45: 44651 | D45: Geral | E45: Alface lisa | F45: cx 12 unid | G45: 25 | H45: 30 | I45: 28.33 | J45: 30 | K45: 30
A46: 2 | B46: 2022 | C46: 44651 | D46: Geral | E46: Almeirão | F46: cx 12 unid | G46: 48 | H46: 48 | I46: 48 | J46: 48 | K46: 48
A47: 2 | B47: 2022 | C47: 44651 | D47: Geral | E47: Batata-doce | F47: cx 18 kg | G47: 25 | H47: 70 | I47: 48.75 | J47: 60 | K47: 50
A48: 2 | B48: 2022 | C48: 44651 | D48: Geral | E48: Berinjela comum | F48: cx 10 kg | G48: 25 | H48: 50 | I48: 40.56 | J48: 50 | K48: 40
A49: 2 | B49: 2022 | C49: 44651 | D49: Geral | E49: Berinjela japonesa | F49: cx 10 kg | G49: 75 | H49: 80 | I49: 77.5 | J49: - | K49: 77.5
A50: 2 | B50: 2022 | C50: 44651 | D50: Geral | E50: Beterraba | F50: cx 20 kg | G50: 60 | H50: 85 | I50: 74.29 | J50: 80 | K50: 80
A51: 2 | B51: 2022 | C51: 44651 | D51: Geral | E51: Brócolos (ninja ou japonês) | F51: cx 12 unid | G51: 60 | H51: 90 | I51: 78 | J51: - | K51: 84
A52: 2 | B52: 2022 | C52: 44651 | D52: Geral | E52: Brócolos ramoso | F52: cx 12 unid | G52: 50 | H52: 72 | I52: 60.67 | J52: 60 | K52: 60
A53: 2 | B53: 2022 | C53: 44651 | D53: Geral | E53: Caqui Fuyu | F53: cx 17 kg | G53: 35 | H53: 35 | I53: 35 | J53: 35 | K53: 35
A54: 2 | B54: 2022 | C54: 44651 | D54: Geral | E54: Caqui Guimbo | F54: cx 17 kg | G54: 35 | H54: 35 | I54: 35 | J54: 35 | K54: 35
A55: 2 | B55: 2022 | C55: 44651 | D55: Geral | E55: Caqui Rama Forte | F55: cx 17 kg | G55: 35 | H55: 35 | I55: 35 | J55: - | K55: 35
A56: 2 | B56: 2022 | C56: 44651 | D56: Geral | E56: Cebolinha | F56: maço 1/2 kg | G56: 3.5 | H56: 4 | I56: 3.83 | J56: 4 | K56: 4
A57: 2 | B57: 2022 | C57: 44651 | D57: Geral | E57: Cenoura | F57: cx 18 kg | G57: 85 | H57: 160 | I57: 126.67 | J57: 160 | K57: 132.5
A58: 2 | B58: 2022 | C58: 44651 | D58: Geral | E58: Chuchu | F58: cx 17 kg | G58: 35 | H58: 55 | I58: 44.3 | J58: 50 | K58: 42.5
A59: 2 | B59: 2022 | C59: 44651 | D59: Geral | E59: Coentro | F59: maço 2 kg | G59: 30 | H59: 35 | I59: 31.67 | J59: 30 | K59: 30
A60: 2 | B60: 2022 | C60: 44651 | D60: Geral | E60: Couve manteiga | F60: cx 12 unid | G60: 24 | H60: 24 | I60: 24 | J60: 24 | K60: 24
A61: 2 | B61: 2022 | C61: 44651 | D61: Geral | E61: Couve-flor | F61: cx 12 unid | G61: 70 | H61: 84 | I61: 75.25 | J61: 73.5 | K61: 73.5
A62: 2 | B62: 2022 | C62: 44651 | D62: Geral | E62: Escarola | F62: cx 12 unid | G62: 25 | H62: 30 | I62: 28.33 | J62: 30 | K62: 30
A63: 2 | B63: 2022 | C63: 44651 | D63: Geral | E63: Espinafre | F63: cx 12 unid | G63: 60 | H63: 60 | I63: 60 | J63: 60 | K63: 60
A64: 2 | B64: 2022 | C64: 44651 | D64: Geral | E64: Goiaba | F64: cx 10 kg | G64: 28 | H64: 50 | I64: 39 | J64: - | K64: 39
A65: 2 | B65: 2022 | C65: 44651 | D65: Geral | E65: Jiló | F65: cx 17 kg | G65: 50 | H65: 80 | I65: 66.36 | J65: 70 | K65: 70
A66: 2 | B66: 2022 | C66: 44651 | D66: Geral | E66: Mexerica Polkan | F66: cx 22 kg | G66: 70 | H66: 70 | I66: 70 | J66: - | K66: 70
...

Sheet GRUPO_ALIMENTAR
A1: grp_id | B1: grp_nome | C1: grp_desc
A2: 1 | B2: A | C2: Verduras (folhosas, flores e hastes) | D2: ="INSERT INTO GRUPO_ALIMENTAR (grp_id, grp_nome, grp_desc) VALUES ("&A2&", '"&B2&"', '"&C2&"');" -> INSERT INTO GRUPO_ALIMENTAR (grp_id, grp_nome, grp_desc) VALUES (1, 'A', 'Verduras (folhosas, flores e hastes)');
A3: 2 | B3: B | C3: Hortaliças condimentares (temperos) | D3: ="INSERT INTO GRUPO_ALIMENTAR (grp_id, grp_nome, grp_desc) VALUES ("&A3&", '"&B3&"', '"&C3&"');" -> INSERT INTO GRUPO_ALIMENTAR (grp_id, grp_nome, grp_desc) VALUES (2, 'B', 'Hortaliças condimentares (temperos)');
A4: 3 | B4: C | C4: Hortaliças legumes (leguminosas (vagens), frutos, raízes tuberosas, tuberculos, bulbos) | D4: ="INSERT INTO GRUPO_ALIMENTAR (grp_id, grp_nome, grp_desc) VALUES ("&A4&", '"&B4&"', '"&C4&"');" -> INSERT INTO GRUPO_ALIMENTAR (grp_id, grp_nome, grp_desc) VALUES (3, 'C', 'Hortaliças legumes (leguminosas (vagens), frutos, raízes tuberosas, tuberculos, bulbos)');
A5: 4 | B5: D | C5: Frutas | D5: ="INSERT INTO GRUPO_ALIMENTAR (grp_id, grp_nome, grp_desc) VALUES ("&A5&", '"&B5&"', '"&C5&"');" -> INSERT INTO GRUPO_ALIMENTAR (grp_id, grp_nome, grp_desc) VALUES (4, 'D', 'Frutas');

Sheet UNIDADE_MEDIDA
A1: umd_id | B1: umd_nome | C1: umd_sigla
A2: 1 | B2: Quilograma | C2: kg | E2: ="INSERT INTO UNIDADE_MEDIDA (umd_id, umd_nome, umd_sigla) VALUES ("&A2&", '"&B2&"', '"&C2&"');" -> INSERT INTO UNIDADE_MEDIDA (umd_id, umd_nome, umd_sigla) VALUES (1, 'Quilograma', 'kg');
A3: 1 | B3: Grama | C3: g | E3: ="INSERT INTO UNIDADE_MEDIDA (umd_id, umd_nome, umd_sigla) VALUES ("&A3&", '"&B3&"', '"&C3&"');" -> INSERT INTO UNIDADE_MEDIDA (umd_id, umd_nome, umd_sigla) VALUES (1, 'Grama', 'g');
A4: 1 | B4: Unidade | C4: un | E4: ="INSERT INTO UNIDADE_MEDIDA (umd_id, umd_nome, umd_sigla) VALUES ("&A4&", '"&B4&"', '"&C4&"');" -> INSERT INTO UNIDADE_MEDIDA (umd_id, umd_nome, umd_sigla) VALUES (1, 'Unidade', 'un');
A5: 1 | B5: Mililitro | C5: ml | E5: ="INSERT INTO UNIDADE_MEDIDA (umd_id, umd_nome, umd_sigla) VALUES ("&A5&", '"&B5&"', '"&C5&"');" -> INSERT INTO UNIDADE_MEDIDA (umd_id, umd_nome, umd_sigla) VALUES (1, 'Mililitro', 'ml');
A6: 1 | B6: Litro | C6: L | E6: ="INSERT INTO UNIDADE_MEDIDA (umd_id, umd_nome, umd_sigla) VALUES ("&A6&", '"&B6&"', '"&C6&"');" -> INSERT INTO UNIDADE_MEDIDA (umd_id, umd_nome, umd_sigla) VALUES (1, 'Litro', 'L');

Sheet BOLETIM
A1: blt_id | B1: blt_numero | C1: blt_ano | D1: blt_data_lev | E1: blt_data_cad
A2: 1 | B2: 1 | C2: 2022 | D2: 44643 | E2: =TODAY() -> 46297 | F2: ="INSERT INTO BOLETIM (blt_id, blt_numero, blt_ano, blt_data_lev, blt_data_cad) VALUES ("&A2&", "&B2&", "&C2&", TO_DATE('"&TEXT(D2,"DD/MM/AAAA")&"', 'DD/MM/YYYY'), SYSDATE);" -> INSERT INTO BOLETIM (blt_id, blt_numero, blt_ano, blt_data_lev, blt_data_cad) VALUES (1, 1, 2022, TO_DATE('23/03/2022', 'DD/MM/YYYY'), SYSDATE);
A3: 2 | B3: 2 | C3: 2022 | D3: 44651 | E3: =TODAY() -> 46297 | F3: ="INSERT INTO BOLETIM (blt_id, blt_numero, blt_ano, blt_data_lev, blt_data_cad) VALUES ("&A3&", "&B3&", "&C3&", TO_DATE('"&TEXT(D3,"DD/MM/AAAA")&"', 'DD/MM/YYYY'), SYSDATE);" -> INSERT INTO BOLETIM (blt_id, blt_numero, blt_ano, blt_data_lev, blt_data_cad) VALUES (2, 2, 2022, TO_DATE('31/03/2022', 'DD/MM/YYYY'), SYSDATE);
A4: 3 | B4: 3 | C4: 2022 | D4: 44658 | E4: =TODAY() -> 46297 | F4: ="INSERT INTO BOLETIM (blt_id, blt_numero, blt_ano, blt_data_lev, blt_data_cad) VALUES ("&A4&", "&B4&", "&C4&", TO_DATE('"&TEXT(D4,"DD/MM/AAAA")&"', 'DD/MM/YYYY'), SYSDATE);" -> INSERT INTO BOLETIM (blt_id, blt_numero, blt_ano, blt_data_lev, blt_data_cad) VALUES (3, 3, 2022, TO_DATE('07/04/2022', 'DD/MM/YYYY'), SYSDATE);
A5: 4 | B5: 4 | C5: 2022 | D5: 44679 | E5: =TODAY() -> 46297 | F5: ="INSERT INTO BOLETIM (blt_id, blt_numero, blt_ano, blt_data_lev, blt_data_cad) VALUES ("&A5&", "&B5&", "&C5&", TO_DATE('"&TEXT(D5,"DD/MM/AAAA")&"', 'DD/MM/YYYY'), SYSDATE);" -> INSERT INTO BOLETIM (blt_id, blt_numero, blt_ano, blt_data_lev, blt_data_cad) VALUES (4, 4, 2022, TO_DATE('28/04/2022', 'DD/MM/YYYY'), SYSDATE);
A6: 5 | B6: 5 | C6: 2022 | D6: 44686 | E6: =TODAY() -> 46297 | F6: ="INSERT INTO BOLETIM (blt_id, blt_numero, blt_ano, blt_data_lev, blt_data_cad) VALUES ("&A6&", "&B6&", "&C6&", TO_DATE('"&TEXT(D6,"DD/MM/AAAA")&"', 'DD/MM/YYYY'), SYSDATE);" -> INSERT INTO BOLETIM (blt_id, blt_numero, blt_ano, blt_data_lev, blt_data_cad) VALUES (5, 5, 2022, TO_DATE('05/05/2022', 'DD/MM/YYYY'), SYSDATE);
A7: 6 | B7: 6 | C7: 2022 | D7: 44693 | E7: =TODAY() -> 46297 | F7: ="INSERT INTO BOLETIM (blt_id, blt_numero, blt_ano, blt_data_lev, blt_data_cad) VALUES ("&A7&", "&B7&", "&C7&", TO_DATE('"&TEXT(D7,"DD/MM/AAAA")&"', 'DD/MM/YYYY'), SYSDATE);" -> INSERT INTO BOLETIM (blt_id, blt_numero, blt_ano, blt_data_lev, blt_data_cad) VALUES (6, 6, 2022, TO_DATE('12/05/2022', 'DD/MM/YYYY'), SYSDATE);
A8: 7 | B8: 7 | C8: 2022 | D8: 44700 | E8: =TODAY() -> 46297 | F8: ="INSERT INTO BOLETIM (blt_id, blt_numero, blt_ano, blt_data_lev, blt_data_cad) VALUES ("&A8&", "&B8&", "&C8&", TO_DATE('"&TEXT(D8,"DD/MM/AAAA")&"', 'DD/MM/YYYY'), SYSDATE);" -> INSERT INTO BOLETIM (blt_id, blt_numero, blt_ano, blt_data_lev, blt_data_cad) VALUES (7, 7, 2022, TO_DATE('19/05/2022', 'DD/MM/YYYY'), SYSDATE);
A9: 8 | B9: 8 | C9: 2022 | D9: 44707 | E9: =TODAY() -> 46297 | F9: ="INSERT INTO BOLETIM (blt_id, blt_numero, blt_ano, blt_data_lev, blt_data_cad) VALUES ("&A9&", "&B9&", "&C9&", TO_DATE('"&TEXT(D9,"DD/MM/AAAA")&"', 'DD/MM/YYYY'), SYSDATE);" -> INSERT INTO BOLETIM (blt_id, blt_numero, blt_ano, blt_data_lev, blt_data_cad) VALUES (8, 8, 2022, TO_DATE('26/05/2022', 'DD/MM/YYYY'), SYSDATE);
A10: 9 | B10: 9 | C10: 2022 | D10: 44714 | E10: =TODAY() -> 46297 | F10: ="INSERT INTO BOLETIM (blt_id, blt_numero, blt_ano, blt_data_lev, blt_data_cad) VALUES ("&A10&", "&B10&", "&C10&", TO_DATE('"&TEXT(D10,"DD/MM/AAAA")&"', 'DD/MM/YYYY'), SYSDATE);" -> INSERT INTO BOLETIM (blt_id, blt_numero, blt_ano, blt_data_lev, blt_data_cad) VALUES (9, 9, 2022, TO_DATE('02/06/2022', 'DD/MM/YYYY'), SYSDATE);
A11: 10 | B11: 10 | C11: 2022 | D11: 44721 | E11: =TODAY() -> 46297 | F11: ="INSERT INTO BOLETIM (blt_id, blt_numero, blt_ano, blt_data_lev, blt_data_cad) VALUES ("&A11&", "&B11&", "&C11&", TO_DATE('"&TEXT(D11,"DD/MM/AAAA")&"', 'DD/MM/YYYY'), SYSDATE);" -> INSERT INTO BOLETIM (blt_id, blt_numero, blt_ano, blt_data_lev, blt_data_cad) VALUES (10, 10, 2022, TO_DATE('09/06/2022', 'DD/MM/YYYY'), SYSDATE);
A12: 11 | B12: 11 | C12: 2022 | D12: 44728 | E12: =TODAY() -> 46297 | F12: ="INSERT INTO BOLETIM (blt_id, blt_numero, blt_ano, blt_data_lev, blt_data_cad) VALUES ("&A12&", "&B12&", "&C12&", TO_DATE('"&TEXT(D12,"DD/MM/AAAA")&"', 'DD/MM/YYYY'), SYSDATE);" -> INSERT INTO BOLETIM (blt_id, blt_numero, blt_ano, blt_data_lev, blt_data_cad) VALUES (11, 11, 2022, TO_DATE('16/06/2022', 'DD/MM/YYYY'), SYSDATE);
A13: 12 | B13: 12 | C13: 2022 | D13: 44735 | E13: =TODAY() -> 46297 | F13: ="INSERT INTO BOLETIM (blt_id, blt_numero, blt_ano, blt_data_lev, blt_data_cad) VALUES ("&A13&", "&B13&", "&C13&", TO_DATE('"&TEXT(D13,"DD/MM/AAAA")&"', 'DD/MM/YYYY'), SYSDATE);" -> INSERT INTO BOLETIM (blt_id, blt_numero, blt_ano, blt_data_lev, blt_data_cad) VALUES (12, 12, 2022, TO_DATE('23/06/2022', 'DD/MM/YYYY'), SYSDATE);
... A129: 128 | B129: 128 | C129: 2025 | D129: 45961 | E129: =TODAY() -> 46297 | F129: ="INSERT INTO BOLETIM (blt_id, blt_numero, blt_ano, blt_data_lev, blt_data_cad) VALUES ("&A129&", "&B129&", "&C129&", TO_DATE('"&TEXT(D129,"DD/MM/AAAA")&"', 'DD/MM/YYYY'), SYSDATE);" -> INSERT INTO BOLETIM (blt_id, blt_numero, blt_ano, blt_data_lev, blt_data_cad) VALUES (128, 128, 2025, TO_DATE('31/10/2025', 'DD/MM/YYYY'), SYSDATE);

Sheet TIPO_APRESENTACAO
A1: tap_id | B1: tap_nome
A2: 1 | B2: caixa | E2: ="INSERT INTO TIPO_APRESENTACAO (tap_id, tap_nome) VALUES ("&A2&", '"&B2&"');" -> INSERT INTO TIPO_APRESENTACAO (tap_id, tap_nome) VALUES (1, 'caixa');
A3: 2 | B3: maço | E3: ="INSERT INTO TIPO_APRESENTACAO (tap_id, tap_nome) VALUES ("&A3&", '"&B3&"');" -> INSERT INTO TIPO_APRESENTACAO (tap_id, tap_nome) VALUES (2, 'maço');
A4: 3 | B4: dúzia | E4: ="INSERT INTO TIPO_APRESENTACAO (tap_id, tap_nome) VALUES ("&A4&", '"&B4&"');" -> INSERT INTO TIPO_APRESENTACAO (tap_id, tap_nome) VALUES (3, 'dúzia');
A5: 4 | B5: saco | E5: ="INSERT INTO TIPO_APRESENTACAO (tap_id, tap_nome) VALUES ("&A5&", '"&B5&"');" -> INSERT INTO TIPO_APRESENTACAO (tap_id, tap_nome) VALUES (4, 'saco');

Sheet CATEGORIA
A1: cat_id | B1: cat_grp_id | C1: cat_nome
A2: 1 | B2: 1 | C2: Folhosas | E2: ="INSERT INTO CATEGORIA (cat_id, cat_grp_id, cat_nome) VALUES ("&A2&", "&B2&", '"&C2&"');" -> INSERT INTO CATEGORIA (cat_id, cat_grp_id, cat_nome) VALUES (1, 1, 'Folhosas');
A3: 2 | B3: 1 | C3: Flores | E3: ="INSERT INTO CATEGORIA (cat_id, cat_grp_id, cat_nome) VALUES ("&A3&", "&B3&", '"&C3&"');" -> INSERT INTO CATEGORIA (cat_id, cat_grp_id, cat_nome) VALUES (2, 1, 'Flores');
A4: 3 | B4: 1 | C4: Hastes | E4: ="INSERT INTO CATEGORIA (cat_id, cat_grp_id, cat_nome) VALUES ("&A4&", "&B4&", '"&C4&"');" -> INSERT INTO CATEGORIA (cat_id, cat_grp_id, cat_nome) VALUES (3, 1, 'Hastes');
A5: 4 | B5: 2 | C5: Temperos | E5: ="INSERT INTO CATEGORIA (cat_id, cat_grp_id, cat_nome) VALUES ("&A5&", "&B5&", '"&C5&"');" -> INSERT INTO CATEGORIA (cat_id, cat_grp_id, cat_nome) VALUES (4, 2, 'Temperos');
A6: 5 | B6: 3 | C6: Leguminosas (vagens) | E6: ="INSERT INTO CATEGORIA (cat_id, cat_grp_id, cat_nome) VALUES ("&A6&", "&B6&", '"&C6&"');" -> INSERT INTO CATEGORIA (cat_id, cat_grp_id, cat_nome) VALUES (5, 3, 'Leguminosas (vagens)');
A7: 6 | B7: 3 | C7: Frutos | E7: ="INSERT INTO CATEGORIA (cat_id, cat_grp_id, cat_nome) VALUES ("&A7&", "&B7&", '"&C7&"');" -> INSERT INTO CATEGORIA (cat_id, cat_grp_id, cat_nome) VALUES (6, 3, 'Frutos');
A8: 7 | B8: 3 | C8: Raízes Tuberosas | E8: ="INSERT INTO CATEGORIA (cat_id, cat_grp_id, cat_nome) VALUES ("&A8&", "&B8&", '"&C8&"');" -> INSERT INTO CATEGORIA (cat_id, cat_grp_id, cat_nome) VALUES (7, 3, 'Raízes Tuberosas');
A9: 8 | B9: 3 | C9: Tubérculos | E9: ="INSERT INTO CATEGORIA (cat_id, cat_grp_id, cat_nome) VALUES ("&A9&", "&B9&", '"&C9&"');" -> INSERT INTO CATEGORIA (cat_id, cat_grp_id, cat_nome) VALUES (8, 3, 'Tubérculos');
A10: 9 | B10: 3 | C10: Bulbos | E10: ="INSERT INTO CATEGORIA (cat_id, cat_grp_id, cat_nome) VALUES ("&A10&", "&B10&", '"&C10&"');" -> INSERT INTO CATEGORIA (cat_id, cat_grp_id, cat_nome) VALUES (9, 3, 'Bulbos');
A11: 10 | B11: 4 | C11: Frutas | E11: ="INSERT INTO CATEGORIA (cat_id, cat_grp_id, cat_nome) VALUES ("&A11&", "&B11&", '"&C11&"');" -> INSERT INTO CATEGORIA (cat_id, cat_grp_id, cat_nome) VALUES (10, 4, 'Frutas');

Sheet PRODUTO
A1: prd_id | B1: prd_cat_id | C1: prd_nome | D1: prd_var | E1: prd_atv
A2: 1 | B2: 1 | C2: Acelga | E2: 1 | G2: ="INSERT INTO PRODUTO (prd_id, prd_cat_id, prd_nome, prd_var, prd_atv) VALUES ("&A2&", "&B2&", '"&C2&"', '"&D2&"', "&E2&");" -> INSERT INTO PRODUTO (prd_id, prd_cat_id, prd_nome, prd_var, prd_atv) VALUES (1, 1, 'Acelga', '', 1);
A3: 2 | B3: 1 | C3: Agrião | E3: 1 | G3: ="INSERT INTO PRODUTO (prd_id, prd_cat_id, prd_nome, prd_var, prd_atv) VALUES ("&A3&", "&B3&", '"&C3&"', '"&D3&"', "&E3&");" -> INSERT INTO PRODUTO (prd_id, prd_cat_id, prd_nome, prd_var, prd_atv) VALUES (2, 1, 'Agrião', '', 1);
A4: 3 | B4: 1 | C4: Alface | D4: Americana | E4: 1 | G4: ="INSERT INTO PRODUTO (prd_id, prd_cat_id, prd_nome, prd_var, prd_atv) VALUES ("&A4&", "&B4&", '"&C4&"', '"&D4&"', "&E4&");" -> INSERT INTO PRODUTO (prd_id, prd_cat_id, prd_nome, prd_var, prd_atv) VALUES (3, 1, 'Alface', 'Americana', 1);
A5: 4 | B5: 1 | C5: Alface | D5: Crespa | E5: 1 | G5: ="INSERT INTO PRODUTO (prd_id, prd_cat_id, prd_nome, prd_var, prd_atv) VALUES ("&A5&", "&B5&", '"&C5&"', '"&D5&"', "&E5&");" -> INSERT INTO PRODUTO (prd_id, prd_cat_id, prd_nome, prd_var, prd_atv) VALUES (4, 1, 'Alface', 'Crespa', 1);
A6: 5 | B6: 1 | C6: Alface | D6: Lisa | E6: 1 | G6: ="INSERT INTO PRODUTO (prd_id, prd_cat_id, prd_nome, prd_var, prd_atv) VALUES ("&A6&", "&B6&", '"&C6&"', '"&D6&"', "&E6&");" -> INSERT INTO PRODUTO (prd_id, prd_cat_id, prd_nome, prd_var, prd_atv) VALUES (5, 1, 'Alface', 'Lisa', 1);
A7: 6 | B7: 1 | C7: Almeirão | E7: 1 | G7: ="INSERT INTO PRODUTO (prd_id, prd_cat_id, prd_nome, prd_var, prd_atv) VALUES ("&A7&", "&B7&", '"&C7&"', '"&D7&"', "&E7&");" -> INSERT INTO PRODUTO (prd_id, prd_cat_id, prd_nome, prd_var, prd_atv) VALUES (6, 1, 'Almeirão', '', 1);
A8: 7 | B8: 2 | C8: Brócolis | D8: Ninja/Japonês | E8: 1 | G8: ="INSERT INTO PRODUTO (prd_id, prd_cat_id, prd_nome, prd_var, prd_atv) VALUES ("&A8&", "&B8&", '"&C8&"', '"&D8&"', "&E8&");" -> INSERT INTO PRODUTO (prd_id, prd_cat_id, prd_nome, prd_var, prd_atv) VALUES (7, 2, 'Brócolis', 'Ninja/Japonês', 1);
A9: 8 | B9: 2 | C9: Brócolis | D9: Ramoso | E9: 1 | G9: ="INSERT INTO PRODUTO (prd_id, prd_cat_id, prd_nome, prd_var, prd_atv) VALUES ("&A9&", "&B9&", '"&C9&"', '"&D9&"', "&E9&");" -> INSERT INTO PRODUTO (prd_id, prd_cat_id, prd_nome, prd_var, prd_atv) VALUES (8, 2, 'Brócolis', 'Ramoso', 1);
A10: 9 | B10: 1 | C10: Couve | D10: Manteiga | E10: 1 | G10: ="INSERT INTO PRODUTO (prd_id, prd_cat_id, prd_nome, prd_var, prd_atv) VALUES ("&A10&", "&B10&", '"&C10&"', '"&D10&"', "&E10&");" -> INSERT INTO PRODUTO (prd_id, prd_cat_id, prd_nome, prd_var, prd_atv) VALUES (9, 1, 'Couve', 'Manteiga', 1);
A11: 10 | B11: 2 | C11: Couve-Flor | E11: 1 | G11: ="INSERT INTO PRODUTO (prd_id, prd_cat_id, prd_nome, prd_var, prd_atv) VALUES ("&A11&", "&B11&", '"&C11&"', '"&D11&"', "&E11&");" -> INSERT INTO PRODUTO (prd_id, prd_cat_id, prd_nome, prd_var, prd_atv) VALUES (10, 2, 'Couve-Flor', '', 1);
A12: 11 | B12: 1 | C12: Escarola | E12: 1 | G12: ="INSERT INTO PRODUTO (prd_id, prd_cat_id, prd_nome, prd_var, prd_atv) VALUES ("&A12&", "&B12&", '"&C12&"', '"&D12&"', "&E12&");" -> INSERT INTO PRODUTO (prd_id, prd_cat_id, prd_nome, prd_var, prd_atv) VALUES (11, 1, 'Escarola', '', 1);
A13: 12 | B13: 1 | C13: Espinafre | E13: 1 | G13: ="INSERT INTO PRODUTO (prd_id, prd_cat_id, prd_nome, prd_var, prd_atv) VALUES ("&A13&", "&B13&", '"&C13&"', '"&D13&"', "&E13&");" -> INSERT INTO PRODUTO (prd_id, prd_cat_id, prd_nome, prd_var, prd_atv) VALUES (12, 1, 'Espinafre', '', 1);
A14: 13 | B14: 7 | C14: Rabanete | E14: 1 | G14: ="INSERT INTO PRODUTO (prd_id, prd_cat_id, prd_nome, prd_var, prd_atv) VALUES ("&A14&", "&B14&", '"&C14&"', '"&D14&"', "&E14&");" -> INSERT INTO PRODUTO (prd_id, prd_cat_id, prd_nome, prd_var, prd_atv) VALUES (13, 7, 'Rabanete', '', 1);
A15: 14 | B15: 1 | C15: Repolho | D15: Roxo | E15: 1 | G15: ="INSERT INTO PRODUTO (prd_id, prd_cat_id, prd_nome, prd_var, prd_atv) VALUES ("&A15&", "&B15&", '"&C15&"', '"&D15&"', "&E15&");" -> INSERT INTO PRODUTO (prd_id, prd_cat_id, prd_nome, prd_var, prd_atv) VALUES (14, 1, 'Repolho', 'Roxo', 1);
A16: 15 | B16: 1 | C16: Repolho | D16: Verde | E16: 1 | G16: ="INSERT INTO PRODUTO (prd_id, prd_cat_id, prd_nome, prd_var, prd_atv) VALUES ("&A16&", "&B16&", '"&C16&"', '"&D16&"', "&E16&");" -> INSERT INTO PRODUTO (prd_id, prd_cat_id, prd_nome, prd_var, prd_atv) VALUES (15, 1, 'Repolho', 'Verde', 1);
A17: 16 | B17: 1 | C17: Rúcula | E17: 1 | G17: ="INSERT INTO PRODUTO (prd_id, prd_cat_id, prd_nome, prd_var, prd_atv) VALUES ("&A17&", "&B17&", '"&C17&"', '"&D17&"', "&E17&");" -> INSERT INTO PRODUTO (prd_id, prd_cat_id, prd_nome, prd_var, prd_atv) VALUES (16, 1, 'Rúcula', '', 1);
A18: 17 | B18: 4 | C18: Cebolinha | E18: 1 | G18: ="INSERT INTO PRODUTO (prd_id, prd_cat_id, prd_nome, prd_var, prd_atv) VALUES ("&A18&", "&B18&", '"&C18&"', '"&D18&"', "&E18&");" -> INSERT INTO PRODUTO (prd_id, prd_cat_id, prd_nome, prd_var, prd_atv) VALUES (17, 4, 'Cebolinha', '', 1);
A19: 18 | B19: 4 | C19: Coentro | E19: 1 | G19: ="INSERT INTO PRODUTO (prd_id, prd_cat_id, prd_nome, prd_var, prd_atv) VALUES ("&A19&", "&B19&", '"&C19&"', '"&D19&"', "&E19&");" -> INSERT INTO PRODUTO (prd_id, prd_cat_id, prd_nome, prd_var, prd_atv) VALUES (18, 4, 'Coentro', '', 1);
A20: 19 | B20: 4 | C20: Salsinha | E20: 1 | G20: ="INSERT INTO PRODUTO (prd_id, prd_cat_id, prd_nome, prd_var, prd_atv) VALUES ("&A20&", "&B20&", '"&C20&"', '"&D20&"', "&E20&");" -> INSERT INTO PRODUTO (prd_id, prd_cat_id, prd_nome, prd_var, prd_atv) VALUES (19, 4, 'Salsinha', '', 1);
A21: 20 | B21: 6 | C21: Abóbora | D21: Cabotiá | E21: 1 | G21: ="INSERT INTO PRODUTO (prd_id, prd_cat_id, prd_nome, prd_var, prd_atv) VALUES ("&A21&", "&B21&", '"&C21&"', '"&D21&"', "&E21&");" -> INSERT INTO PRODUTO (prd_id, prd_cat_id, prd_nome, prd_var, prd_atv) VALUES (20, 6, 'Abóbora', 'Cabotiá', 1);
A22: 21 | B22: 6 | C22: Abobrinha | D22: Italiana | E22: 1 | G22: ="INSERT INTO PRODUTO (prd_id, prd_cat_id, prd_nome, prd_var, prd_atv) VALUES ("&A22&", "&B22&", '"&C22&"', '"&D22&"', "&E22&");" -> INSERT INTO PRODUTO (prd_id, prd_cat_id, prd_nome, prd_var, prd_atv) VALUES (21, 6, 'Abobrinha', 'Italiana', 1);
A23: 22 | B23: 7 | C23: Batata-doce | E23: 1 | G23: ="INSERT INTO PRODUTO (prd_id, prd_cat_id, prd_nome, prd_var, prd_atv) VALUES ("&A23&", "&B23&", '"&C23&"', '"&D23&"', "&E23&");" -> INSERT INTO PRODUTO (prd_id, prd_cat_id, prd_nome, prd_var, prd_atv) VALUES (22, 7, 'Batata-doce', '', 1);
A24: 23 | B24: 6 | C24: Berinjela | D24: Comum | E24: 1 | G24: ="INSERT INTO PRODUTO (prd_id, prd_cat_id, prd_nome, prd_var, prd_atv) VALUES ("&A24&", "&B24&", '"&C24&"', '"&D24&"', "&E24&");" -> INSERT INTO PRODUTO (prd_id, prd_cat_id, prd_nome, prd_var, prd_atv) VALUES (23, 6, 'Berinjela', 'Comum', 1);
A25: 24 | B25: 6 | C25: Berinjela | D25: Japonesa | E25: 1 | G25: ="INSERT INTO PRODUTO (prd_id, prd_cat_id, prd_nome, prd_var, prd_atv) VALUES ("&A25&", "&B25&", '"&C25&"', '"&D25&"', "&E25&");" -> INSERT INTO PRODUTO (prd_id, prd_cat_id, prd_nome, prd_var, prd_atv) VALUES (24, 6, 'Berinjela', 'Japonesa', 1);
A26: 25 | B26: 7 | C26: Beterraba | E26: 1 | G26: ="INSERT INTO PRODUTO (prd_id, prd_cat_id, prd_nome, prd_var, prd_atv) VALUES ("&A26&", "&B26&", '"&C26&"', '"&D26&"', "&E26&");" -> INSERT INTO PRODUTO (prd_id, prd_cat_id, prd_nome, prd_var, prd_atv) VALUES (25, 7, 'Beterraba', '', 1);
A27: 26 | B27: 7 | C27: Cenoura | E27: 1 | G27: ="INSERT INTO PRODUTO (prd_id, prd_cat_id, prd_nome, prd_var, prd_atv) VALUES ("&A27&", "&B27&", '"&C27&"', '"&D27&"', "&E27&");" -> INSERT INTO PRODUTO (prd_id, prd_cat_id, prd_nome, prd_var, prd_atv) VALUES (26, 7, 'Cenoura', '', 1);
A28: 27 | B28: 6 | C28: Chuchu | E28: 1 | G28: ="INSERT INTO PRODUTO (prd_id, prd_cat_id, prd_nome, prd_var, prd_atv) VALUES ("&A28&", "&B28&", '"&C28&"', '"&D28&"', "&E28&");" -> INSERT INTO PRODUTO (prd_id, prd_cat_id, prd_nome, prd_var, prd_atv) VALUES (27, 6, 'Chuchu', '', 1);
A29: 28 | B29: 6 | C29: Jiló | E29: 1 | G29: ="INSERT INTO PRODUTO (prd_id, prd_cat_id, prd_nome, prd_var, prd_atv) VALUES ("&A29&", "&B29&", '"&C29&"', '"&D29&"', "&E29&");" -> INSERT INTO PRODUTO (prd_id, prd_cat_id, prd_nome, prd_var, prd_atv) VALUES (28, 6, 'Jiló', '', 1);
A30: 29 | B30: 7 | C30: Mandioca | E30: 1 | G30: ="INSERT INTO PRODUTO (prd_id, prd_cat_id, prd_nome, prd_var, prd_atv) VALUES ("&A30&", "&B30&", '"&C30&"', '"&D30&"', "&E30&");" -> INSERT INTO PRODUTO (prd_id, prd_cat_id, prd_nome, prd_var, prd_atv) VALUES (29, 7, 'Mandioca', '', 1);
A31: 30 | B31: 6 | C31: Pepino | D31: Comum | E31: 1 | G31: ="INSERT INTO PRODUTO (prd_id, prd_cat_id, prd_nome, prd_var, prd_atv) VALUES ("&A31&", "&B31&", '"&C31&"', '"&D31&"', "&E31&");" -> INSERT INTO PRODUTO (prd_id, prd_cat_id, prd_nome, prd_var, prd_atv) VALUES (30, 6, 'Pepino', 'Comum', 1);
A32: 31 | B32: 6 | C32: Pepino | D32: Japonês | E32: 1 | G32: ="INSERT INTO PRODUTO (prd_id, prd_cat_id, prd_nome, prd_var, prd_atv) VALUES ("&A32&", "&B32&", '"&C32&"', '"&D32&"', "&E32&");" -> INSERT INTO PRODUTO (prd_id, prd_cat_id, prd_nome, prd_var, prd_atv) VALUES (31, 6, 'Pepino', 'Japonês', 1);
A33: 32 | B33: 6 | C33: Pimentão | D33: Verde | E33: 1 | G33: ="INSERT INTO PRODUTO (prd_id, prd_cat_id, prd_nome, prd_var, prd_atv) VALUES ("&A33&", "&B33&", '"&C33&"', '"&D33&"', "&E33&");" -> INSERT INTO PRODUTO (prd_id, prd_cat_id, prd_nome, prd_var, prd_atv) VALUES (32, 6, 'Pimentão', 'Verde', 1);
A34: 33 | B34: 6 | C34: Quiabo | E34: 1 | G34: ="INSERT INTO PRODUTO (prd_id, prd_cat_id, prd_nome, prd_var, prd_atv) VALUES ("&A34&", "&B34&", '"&C34&"', '"&D34&"', "&E34&");" -> INSERT INTO PRODUTO (prd_id, prd_cat_id, prd_nome, prd_var, prd_atv) VALUES (33, 6, 'Quiabo', '', 1);
A35: 34 | B35: 6 | C35: Tomate | D35: Débora | E35: 1 | G35: ="INSERT INTO PRODUTO (prd_id, prd_cat_id, prd_nome, prd_var, prd_atv) VALUES ("&A35&", "&B35&", '"&C35&"', '"&D35&"', "&E35&");" -> INSERT INTO PRODUTO (prd_id, prd_cat_id, prd_nome, prd_var, prd_atv) VALUES (34, 6, 'Tomate', 'Débora', 1);
A36: 35 | B36: 5 | C36: Vagem | D36: Macarrão | E36: 1 | G36: ="INSERT INTO PRODUTO (prd_id, prd_cat_id, prd_nome, prd_var, prd_atv) VALUES ("&A36&", "&B36&", '"&C36&"', '"&D36&"', "&E36&");" -> INSERT INTO PRODUTO (prd_id, prd_cat_id, prd_nome, prd_var, prd_atv) VALUES (35, 5, 'Vagem', 'Macarrão', 1);
A37: 36 | B37: 10 | C37: Caqui | D37: Fuyu | E37: 1 | G37: ="INSERT INTO PRODUTO (prd_id, prd_cat_id, prd_nome, prd_var, prd_atv) VALUES ("&A37&", "&B37&", '"&C37&"', '"&D37&"', "&E37&");" -> INSERT INTO PRODUTO (prd_id, prd_cat_id, prd_nome, prd_var, prd_atv) VALUES (36, 10, 'Caqui', 'Fuyu', 1);
A38: 37 | B38: 10 | C38: Caqui | D38: Guiombo | E38: 1 | G38: ="INSERT INTO PRODUTO (prd_id, prd_cat_id, prd_nome, prd_var, prd_atv) VALUES ("&A38&", "&B38&", '"&C38&"', '"&D38&"', "&E38&");" -> INSERT INTO PRODUTO (prd_id, prd_cat_id, prd_nome, prd_var, prd_atv) VALUES (37, 10, 'Caqui', 'Guiombo', 1);
A39: 38 | B39: 10 | C39: Caqui | D39: Rama Forte | E39: 1 | G39: ="INSERT INTO PRODUTO (prd_id, prd_cat_id, prd_nome, prd_var, prd_atv) VALUES ("&A39&", "&B39&", '"&C39&"', '"&D39&"', "&E39&");" -> INSERT INTO PRODUTO (prd_id, prd_cat_id, prd_nome, prd_var, prd_atv) VALUES (38, 10, 'Caqui', 'Rama Forte', 1);
A40: 39 | B40: 10 | C40: Goiaba | E40: 1 | G40: ="INSERT INTO PRODUTO (prd_id, prd_cat_id, prd_nome, prd_var, prd_atv) VALUES ("&A40&", "&B40&", '"&C40&"', '"&D40&"', "&E40&");" -> INSERT INTO PRODUTO (prd_id, prd_cat_id, prd_nome, prd_var, prd_atv) VALUES (39, 10, 'Goiaba', '', 1);
...

Sheet PRODUTO_APRESENTACAO
A1: pap_id | B1: pap_prd_id | C1: pap_tap_id | D1: pap_qtd | E1: pap_umd_id | F1: pap_atv
A2: 1 | B2: 1 | C2: 3 | D2: 1 | F2: 1 | G2: ="INSERT INTO PRODUTO_APRESENTACAO (pap_id, pap_prd_id, pap_tap_id, pap_qtd, pap_umd_id, pap_atv) VALUES ("&A2&", "&B2&", "&C2&", "&D2&", "&IF(E2="","NULL",E2)&", "&F2&");" -> INSERT INTO PRODUTO_APRESENTACAO (pap_id, pap_prd_id, pap_tap_id, pap_qtd, pap_umd_id, pap_atv) VALUES (1, 1, 3, 1, NULL, 1); | H2: ="UPDATE PRODUTO_APRESENTACAO SET pap_prd_id = "&B2&", pap_tap_id = "&C2&", pap_qtd = "&D2&", pap_umd_id = "&IF(E2="","NULL",E2)&", pap_atv = "&F2&" WHERE pap_id = "&A2&";" -> UPDATE PRODUTO_APRESENTACAO SET pap_prd_id = 1, pap_tap_id = 3, pap_qtd = 1, pap_umd_id = NULL, pap_atv = 1 WHERE pap_id = 1;
A3: 2 | B3: 2 | C3: 3 | D3: 1 | F3: 1 | G3: ="INSERT INTO PRODUTO_APRESENTACAO (pap_id, pap_prd_id, pap_tap_id, pap_qtd, pap_umd_id, pap_atv) VALUES ("&A3&", "&B3&", "&C3&", "&D3&", "&IF(E3="","NULL",E3)&", "&F3&");" -> INSERT INTO PRODUTO_APRESENTACAO (pap_id, pap_prd_id, pap_tap_id, pap_qtd, pap_umd_id, pap_atv) VALUES (2, 2, 3, 1, NULL, 1); | H3: ="UPDATE PRODUTO_APRESENTACAO SET pap_prd_id = "&B3&", pap_tap_id = "&C3&", pap_qtd = "&D3&", pap_umd_id = "&IF(E3="","NULL",E3)&", pap_atv = "&F3&" WHERE pap_id = "&A3&";" -> UPDATE PRODUTO_APRESENTACAO SET pap_prd_id = 2, pap_tap_id = 3, pap_qtd = 1, pap_umd_id = NULL, pap_atv = 1 WHERE pap_id = 2;
A4: 3 | B4: 3 | C4: 3 | D4: 1 | F4: 1 | G4: ="INSERT INTO PRODUTO_APRESENTACAO (pap_id, pap_prd_id, pap_tap_id, pap_qtd, pap_umd_id, pap_atv) VALUES ("&A4&", "&B4&", "&C4&", "&D4&", "&IF(E4="","NULL",E4)&", "&F4&");" -> INSERT INTO PRODUTO_APRESENTACAO (pap_id, pap_prd_id, pap_tap_id, pap_qtd, pap_umd_id, pap_atv) VALUES (3, 3, 3, 1, NULL, 1); | H4: ="UPDATE PRODUTO_APRESENTACAO SET pap_prd_id = "&B4&", pap_tap_id = "&C4&", pap_qtd = "&D4&", pap_umd_id = "&IF(E4="","NULL",E4)&", pap_atv = "&F4&" WHERE pap_id = "&A4&";" -> UPDATE PRODUTO_APRESENTACAO SET pap_prd_id = 3, pap_tap_id = 3, pap_qtd = 1, pap_umd_id = NULL, pap_atv = 1 WHERE pap_id = 3;
A5: 4 | B5: 4 | C5: 3 | D5: 1 | F5: 1 | G5: ="INSERT INTO PRODUTO_APRESENTACAO (pap_id, pap_prd_id, pap_tap_id, pap_qtd, pap_umd_id, pap_atv) VALUES ("&A5&", "&B5&", "&C5&", "&D5&", "&IF(E5="","NULL",E5)&", "&F5&");" -> INSERT INTO PRODUTO_APRESENTACAO (pap_id, pap_prd_id, pap_tap_id, pap_qtd, pap_umd_id, pap_atv) VALUES (4, 4, 3, 1, NULL, 1); | H5: ="UPDATE PRODUTO_APRESENTACAO SET pap_prd_id = "&B5&", pap_tap_id = "&C5&", pap_qtd = "&D5&", pap_umd_id = "&IF(E5="","NULL",E5)&", pap_atv = "&F5&" WHERE pap_id = "&A5&";" -> UPDATE PRODUTO_APRESENTACAO SET pap_prd_id = 4, pap_tap_id = 3, pap_qtd = 1, pap_umd_id = NULL, pap_atv = 1 WHERE pap_id = 4;
A6: 5 | B6: 5 | C6: 3 | D6: 1 | F6: 1 | G6: ="INSERT INTO PRODUTO_APRESENTACAO (pap_id, pap_prd_id, pap_tap_id, pap_qtd, pap_umd_id, pap_atv) VALUES ("&A6&", "&B6&", "&C6&", "&D6&", "&IF(E6="","NULL",E6)&", "&F6&");" -> INSERT INTO PRODUTO_APRESENTACAO (pap_id, pap_prd_id, pap_tap_id, pap_qtd, pap_umd_id, pap_atv) VALUES (5, 5, 3, 1, NULL, 1); | H6: ="UPDATE PRODUTO_APRESENTACAO SET pap_prd_id = "&B6&", pap_tap_id = "&C6&", pap_qtd = "&D6&", pap_umd_id = "&IF(E6="","NULL",E6)&", pap_atv = "&F6&" WHERE pap_id = "&A6&";" -> UPDATE PRODUTO_APRESENTACAO SET pap_prd_id = 5, pap_tap_id = 3, pap_qtd = 1, pap_umd_id = NULL, pap_atv = 1 WHERE pap_id = 5;
A7: 6 | B7: 6 | C7: 3 | D7: 1 | F7: 1 | G7: ="INSERT INTO PRODUTO_APRESENTACAO (pap_id, pap_prd_id, pap_tap_id, pap_qtd, pap_umd_id, pap_atv) VALUES ("&A7&", "&B7&", "&C7&", "&D7&", "&IF(E7="","NULL",E7)&", "&F7&");" -> INSERT INTO PRODUTO_APRESENTACAO (pap_id, pap_prd_id, pap_tap_id, pap_qtd, pap_umd_id, pap_atv) VALUES (6, 6, 3, 1, NULL, 1); | H7: ="UPDATE PRODUTO_APRESENTACAO SET pap_prd_id = "&B7&", pap_tap_id = "&C7&", pap_qtd = "&D7&", pap_umd_id = "&IF(E7="","NULL",E7)&", pap_atv = "&F7&" WHERE pap_id = "&A7&";" -> UPDATE PRODUTO_APRESENTACAO SET pap_prd_id = 6, pap_tap_id = 3, pap_qtd = 1, pap_umd_id = NULL, pap_atv = 1 WHERE pap_id = 6;
A8: 7 | B8: 7 | C8: 3 | D8: 1 | F8: 1 | G8: ="INSERT INTO PRODUTO_APRESENTACAO (pap_id, pap_prd_id, pap_tap_id, pap_qtd, pap_umd_id, pap_atv) VALUES ("&A8&", "&B8&", "&C8&", "&D8&", "&IF(E8="","NULL",E8)&", "&F8&");" -> INSERT INTO PRODUTO_APRESENTACAO (pap_id, pap_prd_id, pap_tap_id, pap_qtd, pap_umd_id, pap_atv) VALUES (7, 7, 3, 1, NULL, 1); | H8: ="UPDATE PRODUTO_APRESENTACAO SET pap_prd_id = "&B8&", pap_tap_id = "&C8&", pap_qtd = "&D8&", pap_umd_id = "&IF(E8="","NULL",E8)&", pap_atv = "&F8&" WHERE pap_id = "&A8&";" -> UPDATE PRODUTO_APRESENTACAO SET pap_prd_id = 7, pap_tap_id = 3, pap_qtd = 1, pap_umd_id = NULL, pap_atv = 1 WHERE pap_id = 7;
A9: 8 | B9: 8 | C9: 3 | D9: 1 | F9: 1 | G9: ="INSERT INTO PRODUTO_APRESENTACAO (pap_id, pap_prd_id, pap_tap_id, pap_qtd, pap_umd_id, pap_atv) VALUES ("&A9&", "&B9&", "&C9&", "&D9&", "&IF(E9="","NULL",E9)&", "&F9&");" -> INSERT INTO PRODUTO_APRESENTACAO (pap_id, pap_prd_id, pap_tap_id, pap_qtd, pap_umd_id, pap_atv) VALUES (8, 8, 3, 1, NULL, 1); | H9: ="UPDATE PRODUTO_APRESENTACAO SET pap_prd_id = "&B9&", pap_tap_id = "&C9&", pap_qtd = "&D9&", pap_umd_id = "&IF(E9="","NULL",E9)&", pap_atv = "&F9&" WHERE pap_id = "&A9&";" -> UPDATE PRODUTO_APRESENTACAO SET pap_prd_id = 8, pap_tap_id = 3, pap_qtd = 1, pap_umd_id = NULL, pap_atv = 1 WHERE pap_id = 8;
A10: 9 | B10: 9 | C10: 3 | D10: 1 | F10: 1 | G10: ="INSERT INTO PRODUTO_APRESENTACAO (pap_id, pap_prd_id, pap_tap_id, pap_qtd, pap_umd_id, pap_atv) VALUES ("&A10&", "&B10&", "&C10&", "&D10&", "&IF(E10="","NULL",E10)&", "&F10&");" -> INSERT INTO PRODUTO_APRESENTACAO (pap_id, pap_prd_id, pap_tap_id, pap_qtd, pap_umd_id, pap_atv) VALUES (9, 9, 3, 1, NULL, 1); | H10: ="UPDATE PRODUTO_APRESENTACAO SET pap_prd_id = "&B10&", pap_tap_id = "&C10&", pap_qtd = "&D10&", pap_umd_id = "&IF(E10="","NULL",E10)&", pap_atv = "&F10&" WHERE pap_id = "&A10&";" -> UPDATE PRODUTO_APRESENTACAO SET pap_prd_id = 9, pap_tap_id = 3, pap_qtd = 1, pap_umd_id = NULL, pap_atv = 1 WHERE pap_id = 9;
A11: 10 | B11: 10 | C11: 3 | D11: 1 | F11: 1 | G11: ="INSERT INTO PRODUTO_APRESENTACAO (pap_id, pap_prd_id, pap_tap_id, pap_qtd, pap_umd_id, pap_atv) VALUES ("&A11&", "&B11&", "&C11&", "&D11&", "&IF(E11="","NULL",E11)&", "&F11&");" -> INSERT INTO PRODUTO_APRESENTACAO (pap_id, pap_prd_id, pap_tap_id, pap_qtd, pap_umd_id, pap_atv) VALUES (10, 10, 3, 1, NULL, 1); | H11: ="UPDATE PRODUTO_APRESENTACAO SET pap_prd_id = "&B11&", pap_tap_id = "&C11&", pap_qtd = "&D11&", pap_umd_id = "&IF(E11="","NULL",E11)&", pap_atv = "&F11&" WHERE pap_id = "&A11&";" -> UPDATE PRODUTO_APRESENTACAO SET pap_prd_id = 10, pap_tap_id = 3, pap_qtd = 1, pap_umd_id = NULL, pap_atv = 1 WHERE pap_id = 10;
A12: 11 | B12: 11 | C12: 3 | D12: 1 | F12: 1 | G12: ="INSERT INTO PRODUTO_APRESENTACAO (pap_id, pap_prd_id, pap_tap_id, pap_qtd, pap_umd_id, pap_atv) VALUES ("&A12&", "&B12&", "&C12&", "&D12&", "&IF(E12="","NULL",E12)&", "&F12&");" -> INSERT INTO PRODUTO_APRESENTACAO (pap_id, pap_prd_id, pap_tap_id, pap_qtd, pap_umd_id, pap_atv) VALUES (11, 11, 3, 1, NULL, 1); | H12: ="UPDATE PRODUTO_APRESENTACAO SET pap_prd_id = "&B12&", pap_tap_id = "&C12&", pap_qtd = "&D12&", pap_umd_id = "&IF(E12="","NULL",E12)&", pap_atv = "&F12&" WHERE pap_id = "&A12&";" -> UPDATE PRODUTO_APRESENTACAO SET pap_prd_id = 11, pap_tap_id = 3, pap_qtd = 1, pap_umd_id = NULL, pap_atv = 1 WHERE pap_id = 11;
A13: 12 | B13: 12 | C13: 3 | D13: 1 | F13: 1 | G13: ="INSERT INTO PRODUTO_APRESENTACAO (pap_id, pap_prd_id, pap_tap_id, pap_qtd, pap_umd_id, pap_atv) VALUES ("&A13&", "&B13&", "&C13&", "&D13&", "&IF(E13="","NULL",E13)&", "&F13&");" -> INSERT INTO PRODUTO_APRESENTACAO (pap_id, pap_prd_id, pap_tap_id, pap_qtd, pap_umd_id, pap_atv) VALUES (12, 12, 3, 1, NULL, 1); | H13: ="UPDATE PRODUTO_APRESENTACAO SET pap_prd_id = "&B13&", pap_tap_id = "&C13&", pap_qtd = "&D13&", pap_umd_id = "&IF(E13="","NULL",E13)&", pap_atv = "&F13&" WHERE pap_id = "&A13&";" -> UPDATE PRODUTO_APRESENTACAO SET pap_prd_id = 12, pap_tap_id = 3, pap_qtd = 1, pap_umd_id = NULL, pap_atv = 1 WHERE pap_id = 12;
... A17: 16 | B17: 16 | C17: 3 | D17: 1 | F17: 1 | G17: ="INSERT INTO PRODUTO_APRESENTACAO (pap_id, pap_prd_id, pap_tap_id, pap_qtd, pap_umd_id, pap_atv) VALUES ("&A17&", "&B17&", "&C17&", "&D17&", "&IF(E17="","NULL",E17)&", "&F17&");" -> INSERT INTO PRODUTO_APRESENTACAO (pap_id, pap_prd_id, pap_tap_id, pap_qtd, pap_umd_id, pap_atv) VALUES (16, 16, 3, 1, NULL, 1); | H17: ="UPDATE PRODUTO_APRESENTACAO SET pap_prd_id = "&B17&", pap_tap_id = "&C17&", pap_qtd = "&D17&", pap_umd_id = "&IF(E17="","NULL",E17)&", pap_atv = "&F17&" WHERE pap_id = "&A17&";" -> UPDATE PRODUTO_APRESENTACAO SET pap_prd_id = 16, pap_tap_id = 3, pap_qtd = 1, pap_umd_id = NULL, pap_atv = 1 WHERE pap_id = 16;
A18: 17 | B18: 17 | C18: 2 | D18: 0.5 | E18: 1 | F18: 1 | G18: ="INSERT INTO PRODUTO_APRESENTACAO (pap_id, pap_prd_id, pap_tap_id, pap_qtd, pap_umd_id, pap_atv) VALUES ("&A18&", "&B18&", "&C18&", "&D18&", "&IF(E18="","NULL",E18)&", "&F18&");" -> INSERT INTO PRODUTO_APRESENTACAO (pap_id, pap_prd_id, pap_tap_id, pap_qtd, pap_umd_id, pap_atv) VALUES (17, 17, 2, 0.5, 1, 1); | H18: ="UPDATE PRODUTO_APRESENTACAO SET pap_prd_id = "&B18&", pap_tap_id = "&C18&", pap_qtd = "&D18&", pap_umd_id = "&IF(E18="","NULL",E18)&", pap_atv = "&F18&" WHERE pap_id = "&A18&";" -> UPDATE PRODUTO_APRESENTACAO SET pap_prd_id = 17, pap_tap_id = 2, pap_qtd = 0.5, pap_umd_id = 1, pap_atv = 1 WHERE pap_id = 17;
A19: 18 | B19: 18 | C19: 2 | D19: 2 | E19: 1 | F19: 1 | G19: ="INSERT INTO PRODUTO_APRESENTACAO (pap_id, pap_prd_id, pap_tap_id, pap_qtd, pap_umd_id, pap_atv) VALUES ("&A19&", "&B19&", "&C19&", "&D19&", "&IF(E19="","NULL",E19)&", "&F19&");" -> INSERT INTO PRODUTO_APRESENTACAO (pap_id, pap_prd_id, pap_tap_id, pap_qtd, pap_umd_id, pap_atv) VALUES (18, 18, 2, 2, 1, 1); | H19: ="UPDATE PRODUTO_APRESENTACAO SET pap_prd_id = "&B19&", pap_tap_id = "&C19&", pap_qtd = "&D19&", pap_umd_id = "&IF(E19="","NULL",E19)&", pap_atv = "&F19&" WHERE pap_id = "&A19&";" -> UPDATE PRODUTO_APRESENTACAO SET pap_prd_id = 18, pap_tap_id = 2, pap_qtd = 2, pap_umd_id = 1, pap_atv = 1 WHERE pap_id = 18;
A20: 19 | B20: 19 | C20: 2 | D20: 2 | E20: 1 | F20: 1 | G20: ="INSERT INTO PRODUTO_APRESENTACAO (pap_id, pap_prd_id, pap_tap_id, pap_qtd, pap_umd_id, pap_atv) VALUES ("&A20&", "&B20&", "&C20&", "&D20&", "&IF(E20="","NULL",E20)&", "&F20&");" -> INSERT INTO PRODUTO_APRESENTACAO (pap_id, pap_prd_id, pap_tap_id, pap_qtd, pap_umd_id, pap_atv) VALUES (19, 19, 2, 2, 1, 1); | H20: ="UPDATE PRODUTO_APRESENTACAO SET pap_prd_id = "&B20&", pap_tap_id = "&C20&", pap_qtd = "&D20&", pap_umd_id = "&IF(E20="","NULL",E20)&", pap_atv = "&F20&" WHERE pap_id = "&A20&";" -> UPDATE PRODUTO_APRESENTACAO SET pap_prd_id = 19, pap_tap_id = 2, pap_qtd = 2, pap_umd_id = 1, pap_atv = 1 WHERE pap_id = 19;
A21: 20 | B21: 20 | C21: 1 | D21: 30 | E21: 1 | F21: 1 | G21: ="INSERT INTO PRODUTO_APRESENTACAO (pap_id, pap_prd_id, pap_tap_id, pap_qtd, pap_umd_id, pap_atv) VALUES ("&A21&", "&B21&", "&C21&", "&D21&", "&IF(E21="","NULL",E21)&", "&F21&");" -> INSERT INTO PRODUTO_APRESENTACAO (pap_id, pap_prd_id, pap_tap_id, pap_qtd, pap_umd_id, pap_atv) VALUES (20, 20, 1, 30, 1, 1); | H21: ="UPDATE PRODUTO_APRESENTACAO SET pap_prd_id = "&B21&", pap_tap_id = "&C21&", pap_qtd = "&D21&", pap_umd_id = "&IF(E21="","NULL",E21)&", pap_atv = "&F21&" WHERE pap_id = "&A21&";" -> UPDATE PRODUTO_APRESENTACAO SET pap_prd_id = 20, pap_tap_id = 1, pap_qtd = 30, pap_umd_id = 1, pap_atv = 1 WHERE pap_id = 20;
A22: 21 | B22: 21 | C22: 1 | D22: 17 | E22: 1 | F22: 1 | G22: ="INSERT INTO PRODUTO_APRESENTACAO (pap_id, pap_prd_id, pap_tap_id, pap_qtd, pap_umd_id, pap_atv) VALUES ("&A22&", "&B22&", "&C22&", "&D22&", "&IF(E22="","NULL",E22)&", "&F22&");" -> INSERT INTO PRODUTO_APRESENTACAO (pap_id, pap_prd_id, pap_tap_id, pap_qtd, pap_umd_id, pap_atv) VALUES (21, 21, 1, 17, 1, 1); | H22: ="UPDATE PRODUTO_APRESENTACAO SET pap_prd_id = "&B22&", pap_tap_id = "&C22&", pap_qtd = "&D22&", pap_umd_id = "&IF(E22="","NULL",E22)&", pap_atv = "&F22&" WHERE pap_id = "&A22&";" -> UPDATE PRODUTO_APRESENTACAO SET pap_prd_id = 21, pap_tap_id = 1, pap_qtd = 17, pap_umd_id = 1, pap_atv = 1 WHERE pap_id = 21;
A23: 22 | B23: 22 | C23: 1 | D23: 18 | E23: 1 | F23: 1 | G23: ="INSERT INTO PRODUTO_APRESENTACAO (pap_id, pap_prd_id, pap_tap_id, pap_qtd, pap_umd_id, pap_atv) VALUES ("&A23&", "&B23&", "&C23&", "&D23&", "&IF(E23="","NULL",E23)&", "&F23&");" -> INSERT INTO PRODUTO_APRESENTACAO (pap_id, pap_prd_id, pap_tap_id, pap_qtd, pap_umd_id, pap_atv) VALUES (22, 22, 1, 18, 1, 1); | H23: ="UPDATE PRODUTO_APRESENTACAO SET pap_prd_id = "&B23&", pap_tap_id = "&C23&", pap_qtd = "&D23&", pap_umd_id = "&IF(E23="","NULL",E23)&", pap_atv = "&F23&" WHERE pap_id = "&A23&";" -> UPDATE PRODUTO_APRESENTACAO SET pap_prd_id = 22, pap_tap_id = 1, pap_qtd = 18, pap_umd_id = 1, pap_atv = 1 WHERE pap_id = 22;
A24: 23 | B24: 23 | C24: 1 | D24: 10 | E24: 1 | F24: 1 | G24: ="INSERT INTO PRODUTO_APRESENTACAO (pap_id, pap_prd_id, pap_tap_id, pap_qtd, pap_umd_id, pap_atv) VALUES ("&A24&", "&B24&", "&C24&", "&D24&", "&IF(E24="","NULL",E24)&", "&F24&");" -> INSERT INTO PRODUTO_APRESENTACAO (pap_id, pap_prd_id, pap_tap_id, pap_qtd, pap_umd_id, pap_atv) VALUES (23, 23, 1, 10, 1, 1); | H24: ="UPDATE PRODUTO_APRESENTACAO SET pap_prd_id = "&B24&", pap_tap_id = "&C24&", pap_qtd = "&D24&", pap_umd_id = "&IF(E24="","NULL",E24)&", pap_atv = "&F24&" WHERE pap_id = "&A24&";" -> UPDATE PRODUTO_APRESENTACAO SET pap_prd_id = 23, pap_tap_id = 1, pap_qtd = 10, pap_umd_id = 1, pap_atv = 1 WHERE pap_id = 23;
A25: 24 | B25: 24 | C25: 1 | D25: 10 | E25: 1 | F25: 1 | G25: ="INSERT INTO PRODUTO_APRESENTACAO (pap_id, pap_prd_id, pap_tap_id, pap_qtd, pap_umd_id, pap_atv) VALUES ("&A25&", "&B25&", "&C25&", "&D25&", "&IF(E25="","NULL",E25)&", "&F25&");" -> INSERT INTO PRODUTO_APRESENTACAO (pap_id, pap_prd_id, pap_tap_id, pap_qtd, pap_umd_id, pap_atv) VALUES (24, 24, 1, 10, 1, 1); | H25: ="UPDATE PRODUTO_APRESENTACAO SET pap_prd_id = "&B25&", pap_tap_id = "&C25&", pap_qtd = "&D25&", pap_umd_id = "&IF(E25="","NULL",E25)&", pap_atv = "&F25&" WHERE pap_id = "&A25&";" -> UPDATE PRODUTO_APRESENTACAO SET pap_prd_id = 24, pap_tap_id = 1, pap_qtd = 10, pap_umd_id = 1, pap_atv = 1 WHERE pap_id = 24;
A26: 25 | B26: 25 | C26: 1 | D26: 20 | E26: 1 | F26: 1 | G26: ="INSERT INTO PRODUTO_APRESENTACAO (pap_id, pap_prd_id, pap_tap_id, pap_qtd, pap_umd_id, pap_atv) VALUES ("&A26&", "&B26&", "&C26&", "&D26&", "&IF(E26="","NULL",E26)&", "&F26&");" -> INSERT INTO PRODUTO_APRESENTACAO (pap_id, pap_prd_id, pap_tap_id, pap_qtd, pap_umd_id, pap_atv) VALUES (25, 25, 1, 20, 1, 1); | H26: ="UPDATE PRODUTO_APRESENTACAO SET pap_prd_id = "&B26&", pap_tap_id = "&C26&", pap_qtd = "&D26&", pap_umd_id = "&IF(E26="","NULL",E26)&", pap_atv = "&F26&" WHERE pap_id = "&A26&";" -> UPDATE PRODUTO_APRESENTACAO SET pap_prd_id = 25, pap_tap_id = 1, pap_qtd = 20, pap_umd_id = 1, pap_atv = 1 WHERE pap_id = 25;
A27: 26 | B27: 26 | C27: 1 | D27: 18 | E27: 1 | F27: 1 | G27: ="INSERT INTO PRODUTO_APRESENTACAO (pap_id, pap_prd_id, pap_tap_id, pap_qtd, pap_umd_id, pap_atv) VALUES ("&A27&", "&B27&", "&C27&", "&D27&", "&IF(E27="","NULL",E27)&", "&F27&");" -> INSERT INTO PRODUTO_APRESENTACAO (pap_id, pap_prd_id, pap_tap_id, pap_qtd, pap_umd_id, pap_atv) VALUES (26, 26, 1, 18, 1, 1); | H27: ="UPDATE PRODUTO_APRESENTACAO SET pap_prd_id = "&B27&", pap_tap_id = "&C27&", pap_qtd = "&D27&", pap_umd_id = "&IF(E27="","NULL",E27)&", pap_atv = "&F27&" WHERE pap_id = "&A27&";" -> UPDATE PRODUTO_APRESENTACAO SET pap_prd_id = 26, pap_tap_id = 1, pap_qtd = 18, pap_umd_id = 1, pap_atv = 1 WHERE pap_id = 26;
A28: 27 | B28: 27 | C28: 1 | D28: 18 | E28: 1 | F28: 1 | G28: ="INSERT INTO PRODUTO_APRESENTACAO (pap_id, pap_prd_id, pap_tap_id, pap_qtd, pap_umd_id, pap_atv) VALUES ("&A28&", "&B28&", "&C28&", "&D28&", "&IF(E28="","NULL",E28)&", "&F28&");" -> INSERT INTO PRODUTO_APRESENTACAO (pap_id, pap_prd_id, pap_tap_id, pap_qtd, pap_umd_id, pap_atv) VALUES (27, 27, 1, 18, 1, 1); | H28: ="UPDATE PRODUTO_APRESENTACAO SET pap_prd_id = "&B28&", pap_tap_id = "&C28&", pap_qtd = "&D28&", pap_umd_id = "&IF(E28="","NULL",E28)&", pap_atv = "&F28&" WHERE pap_id = "&A28&";" -> UPDATE PRODUTO_APRESENTACAO SET pap_prd_id = 27, pap_tap_id = 1, pap_qtd = 18, pap_umd_id = 1, pap_atv = 1 WHERE pap_id = 27;
