Workbook

Sheet Boletins Nuppa Site
A1: Boletim | B1: Data | C1: Grupo | D1: Produto | E1: Unidade | F1: Comum | G1: Mínimo | H1: Máximo | I1: Média | J1: Mediana
A2: 37/2023 | B2: 44931 | C2: GRUPO A - Verduras (Folhosas, Flores e Hastes) | D2: Acelga | E2: 12 unidades | G2: 32 | H2: 32 | I2: 32 | J2: 32
A3: 37/2023 | B3: 44931 | C3: GRUPO A - Verduras (Folhosas, Flores e Hastes) | D3: Agrião | E3: 12 unidades | G3: 60 | H3: 60 | I3: 60 | J3: 60
A4: 37/2023 | B4: 44931 | C4: GRUPO A - Verduras (Folhosas, Flores e Hastes) | D4: Alface Americana | E4: 12 unidades | G4: 24 | H4: 36 | I4: 30 | J4: 30
A5: 37/2023 | B5: 44931 | C5: GRUPO A - Verduras (Folhosas, Flores e Hastes) | D5: Alface crespa | E5: 12 unidades | G5: 18 | H5: 30 | I5: 24 | J5: 24
A6: 37/2023 | B6: 44931 | C6: GRUPO A - Verduras (Folhosas, Flores e Hastes) | D6: Alface lisa | E6: 12 unidades | G6: 18 | H6: 30 | I6: 24 | J6: 24
A7: 37/2023 | B7: 44931 | C7: GRUPO A - Verduras (Folhosas, Flores e Hastes) | D7: Almeirão | E7: 12 unidades | G7: 48 | H7: 48 | I7: 48 | J7: 48
A8: 37/2023 | B8: 44931 | C8: GRUPO A - Verduras (Folhosas, Flores e Hastes) | D8: Brócolos ninja/japonês | E8: 12 unidades | G8: 60 | H8: 60 | I8: 60 | J8: 60
A9: 37/2023 | B9: 44931 | C9: GRUPO A - Verduras (Folhosas, Flores e Hastes) | D9: Brócolos ramoso | E9: 12 unidades | F9: 48 | G9: 48 | H9: 60 | I9: 52 | J9: 48
A10: 37/2023 | B10: 44931 | C10: GRUPO A - Verduras (Folhosas, Flores e Hastes) | D10: Couve-Manteiga | E10: 12 unidades | F10: 15 | G10: 15 | H10: 24 | I10: 18 | J10: 15
A11: 37/2023 | B11: 44931 | C11: GRUPO A - Verduras (Folhosas, Flores e Hastes) | D11: Couve | G11: 60 | H11: 60 | I11: 60 | J11: 60
A12: 37/2023 | B12: 44931 | C12: GRUPO A - Verduras (Folhosas, Flores e Hastes) | D12: Escarola | E12: 12 unidades | G12: 18 | H12: 30 | I12: 24 | J12: 24
A13: 37/2023 | B13: 44931 | C13: GRUPO A - Verduras (Folhosas, Flores e Hastes) | D13: Espinafre | E13: 12 unidades | G13: 42 | H13: 54 | I13: 48 | J13: 48
A14: 37/2023 | B14: 44931 | C14: GRUPO A - Verduras (Folhosas, Flores e Hastes) | D14: Rabanete | E14: 12 maços | G14: 36 | H14: 48 | I14: 42 | J14: 42
A15: 37/2023 | B15: 44931 | C15: GRUPO A - Verduras (Folhosas, Flores e Hastes) | D15: Repolho roxo | E15: 12 unidades | G15: 60 | H15: 60 | I15: 60 | J15: 60
A16: 37/2023 | B16: 44931 | C16: GRUPO A - Verduras (Folhosas, Flores e Hastes) | D16: Repolho Verde | E16: 12 unidades | G16: 24 | H16: 36 | I16: 30 | J16: 30
A17: 37/2023 | B17: 44931 | C17: GRUPO A - Verduras (Folhosas, Flores e Hastes) | D17: Rúcula | E17: 12 unidades | F17: 42 | G17: 36 | H17: 42 | I17: 40 | J17: 42
A18: 37/2023 | B18: 44931 | C18: GRUPO B - Hortaliças Condimentares (Temperos) | D18: Cebolinha | E18: Maço 0,5 kg | F18: 4 | G18: 3 | H18: 4 | I18: 3.67 | J18: 4
A19: 37/2023 | B19: 44931 | C19: GRUPO B - Hortaliças Condimentares (Temperos) | D19: Coentro | E19: Maço 2 kg | F19: 25 | G19: 25 | H19: 25 | I19: 25 | J19: 25
A20: 37/2023 | B20: 44931 | C20: GRUPO B - Hortaliças Condimentares (Temperos) | D20: Salsinha | E20: Maço 2 kg | F20: 25 | G20: 20 | H20: 25 | I20: 22.5 | J20: 22.5
A21: 37/2023 | B21: 44931 | C21: GRUPO C - Hortaliças Legumes (Leguminosas (Vagens), Frutos, Raízes Tuberosas, Tubérculos e Bulbos) | D21: Abobrinha Italiana | E21: 17 kg | F21: 60 | G21: 50 | H21: 60 | I21: 57.5 | J21: 60
A22: 37/2023 | B22: 44931 | C22: GRUPO C - Hortaliças Legumes (Leguminosas (Vagens), Frutos, Raízes Tuberosas, Tubérculos e Bulbos) | D22: Batata-doce | E22: 18 kg | F22: 50 | G22: 50 | H22: 65 | I22: 55 | J22: 50
A23: 37/2023 | B23: 44931 | C23: GRUPO C - Hortaliças Legumes (Leguminosas (Vagens), Frutos, Raízes Tuberosas, Tubérculos e Bulbos) | D23: Berinjela comum | E23: 10 kg | F23: 40 | G23: 40 | H23: 50 | I23: 44.17 | J23: 42.5
A24: 37/2023 | B24: 44931 | C24: GRUPO C - Hortaliças Legumes (Leguminosas (Vagens), Frutos, Raízes Tuberosas, Tubérculos e Bulbos) | D24: Berinjela japonesa | E24: 10 kg
A25: 37/2023 | B25: 44931 | C25: GRUPO C - Hortaliças Legumes (Leguminosas (Vagens), Frutos, Raízes Tuberosas, Tubérculos e Bulbos) | D25: Beterraba | E25: 20 kg | G25: 48 | H25: 60 | I25: 52.67 | J25: 50
A26: 37/2023 | B26: 44931 | C26: GRUPO C - Hortaliças Legumes (Leguminosas (Vagens), Frutos, Raízes Tuberosas, Tubérculos e Bulbos) | D26: Cenoura | E26: 18 kg | F26: 55 | G26: 50 | H26: 60 | I26: 55 | J26: 55
A27: 37/2023 | B27: 44931 | C27: GRUPO C - Hortaliças Legumes (Leguminosas (Vagens), Frutos, Raízes Tuberosas, Tubérculos e Bulbos) | D27: Chuchu | E27: 18 kg | F27: 40 | G27: 30 | H27: 50 | I27: 40 | J27: 40
A28: 37/2023 | B28: 44931 | C28: GRUPO C - Hortaliças Legumes (Leguminosas (Vagens), Frutos, Raízes Tuberosas, Tubérculos e Bulbos) | D28: Jiló | E28: 17 kg | F28: 50 | G28: 50 | H28: 70 | I28: 56.67 | J28: 50
A29: 37/2023 | B29: 44931 | C29: GRUPO C - Hortaliças Legumes (Leguminosas (Vagens), Frutos, Raízes Tuberosas, Tubérculos e Bulbos) | D29: Mandioca | E29: 18 kg
A30: 37/2023 | B30: 44931 | C30: GRUPO C - Hortaliças Legumes (Leguminosas (Vagens), Frutos, Raízes Tuberosas, Tubérculos e Bulbos) | D30: Pepino comum | E30: 17 kg | F30: 50 | G30: 40 | H30: 60 | I30: 50 | J30: 50
A31: 37/2023 | B31: 44931 | C31: GRUPO C - Hortaliças Legumes (Leguminosas (Vagens), Frutos, Raízes Tuberosas, Tubérculos e Bulbos) | D31: Pepino japonês | E31: 17 kg | F31: 50 | G31: 50 | H31: 60 | I31: 55 | J31: 55
A32: 37/2023 | B32: 44931 | C32: GRUPO C - Hortaliças Legumes (Leguminosas (Vagens), Frutos, Raízes Tuberosas, Tubérculos e Bulbos) | D32: Pimentão verde | E32: 10 kg | G32: 30 | H32: 50 | I32: 40 | J32: 40
A33: 37/2023 | B33: 44931 | C33: GRUPO C - Hortaliças Legumes (Leguminosas (Vagens), Frutos, Raízes Tuberosas, Tubérculos e Bulbos) | D33: Quiabo | E33: 12 kg | F33: 70 | G33: 60 | H33: 80 | I33: 68.33 | J33: 70
A34: 37/2023 | B34: 44931 | C34: GRUPO C - Hortaliças Legumes (Leguminosas (Vagens), Frutos, Raízes Tuberosas, Tubérculos e Bulbos) | D34: Tomate Débora | E34: 17 kg | F34: 100 | G34: 90 | H34: 110 | I34: 100 | J34: 100
A35: 37/2023 | B35: 44931 | C35: GRUPO C - Hortaliças Legumes (Leguminosas (Vagens), Frutos, Raízes Tuberosas, Tubérculos e Bulbos) | D35: Vagem macarrão | E35: 17 kg | F35: 80 | G35: 70 | H35: 100 | I35: 83 | J35: 80
A36: 37/2023 | B36: 44931 | C36: GRUPO D - Frutas | D36: Caqui Fuyu | E36: 17 kg
A37: 37/2023 | B37: 44931 | C37: GRUPO D - Frutas | D37: Caqui Guimbo | E37: 17 kg
A38: 37/2023 | B38: 44931 | C38: GRUPO D - Frutas | D38: Caqui Rama Forte | E38: 17 kg
A39: 37/2023 | B39: 44931 | C39: GRUPO D - Frutas | D39: Goiaba | E39: 10 kg
A40: 37/2023 | B40: 44931 | C40: GRUPO D - Frutas | D40: Mexerica Polkan | E40: 22 kg
...

Sheet COTACAO
A1: cot_id | B1: blt_id | C1: pap_id | D1: cot_prc_comum | E1: cot_prc_min | F1: cot_prc_max | G1: cot_prc_med | H1: cot_prc_mediana
A2: 1 | B2: 1 | C2: 1 | D2: =IF('Boletins Nuppa Site'!F2<>0,'Boletins Nuppa Site'!F2,"NULL") -> NULL | E2: =IF('Boletins Nuppa Site'!G2<>0,'Boletins Nuppa Site'!G2,"NULL") -> 32 | F2: =IF('Boletins Nuppa Site'!H2<>0,'Boletins Nuppa Site'!H2,"NULL") -> 32 | G2: =IF('Boletins Nuppa Site'!I2<>0,'Boletins Nuppa Site'!I2,"NULL") -> 32 | H2: =IF('Boletins Nuppa Site'!J2<>0,'Boletins Nuppa Site'!J2,"NULL") -> 32 | J2: ="INSERT INTO COTACAO (blt_id, pap_id, cot_prc_comum, cot_prc_min, cot_prc_max, cot_prc_med, cot_prc_mediana) VALUES ("&B2&", "&C2&", "&D2&", "&E2&", "&F2&", "&G2&", "&H2&");" -> INSERT INTO COTACAO (blt_id, pap_id, cot_prc_comum, cot_prc_min, cot_prc_max, cot_prc_med, cot_prc_mediana) VALUES (1, 1, NULL, 32, 32, 32, 32);
A3: 2 | B3: 1 | C3: 2 | D3: =IF('Boletins Nuppa Site'!F3<>0,'Boletins Nuppa Site'!F3,"NULL") -> NULL | E3: =IF('Boletins Nuppa Site'!G3<>0,'Boletins Nuppa Site'!G3,"NULL") -> 60 | F3: =IF('Boletins Nuppa Site'!H3<>0,'Boletins Nuppa Site'!H3,"NULL") -> 60 | G3: =IF('Boletins Nuppa Site'!I3<>0,'Boletins Nuppa Site'!I3,"NULL") -> 60 | H3: =IF('Boletins Nuppa Site'!J3<>0,'Boletins Nuppa Site'!J3,"NULL") -> 60 | J3: ="INSERT INTO COTACAO (blt_id, pap_id, cot_prc_comum, cot_prc_min, cot_prc_max, cot_prc_med, cot_prc_mediana) VALUES ("&B3&", "&C3&", "&D3&", "&E3&", "&F3&", "&G3&", "&H3&");" -> INSERT INTO COTACAO (blt_id, pap_id, cot_prc_comum, cot_prc_min, cot_prc_max, cot_prc_med, cot_prc_mediana) VALUES (1, 2, NULL, 60, 60, 60, 60);
A4: 3 | B4: 1 | C4: 3 | D4: =IF('Boletins Nuppa Site'!F4<>0,'Boletins Nuppa Site'!F4,"NULL") -> NULL | E4: =IF('Boletins Nuppa Site'!G4<>0,'Boletins Nuppa Site'!G4,"NULL") -> 24 | F4: =IF('Boletins Nuppa Site'!H4<>0,'Boletins Nuppa Site'!H4,"NULL") -> 36 | G4: =IF('Boletins Nuppa Site'!I4<>0,'Boletins Nuppa Site'!I4,"NULL") -> 30 | H4: =IF('Boletins Nuppa Site'!J4<>0,'Boletins Nuppa Site'!J4,"NULL") -> 30 | J4: ="INSERT INTO COTACAO (blt_id, pap_id, cot_prc_comum, cot_prc_min, cot_prc_max, cot_prc_med, cot_prc_mediana) VALUES ("&B4&", "&C4&", "&D4&", "&E4&", "&F4&", "&G4&", "&H4&");" -> INSERT INTO COTACAO (blt_id, pap_id, cot_prc_comum, cot_prc_min, cot_prc_max, cot_prc_med, cot_prc_mediana) VALUES (1, 3, NULL, 24, 36, 30, 30);
A5: 4 | B5: 1 | C5: 4 | D5: =IF('Boletins Nuppa Site'!F5<>0,'Boletins Nuppa Site'!F5,"NULL") -> NULL | E5: =IF('Boletins Nuppa Site'!G5<>0,'Boletins Nuppa Site'!G5,"NULL") -> 18 | F5: =IF('Boletins Nuppa Site'!H5<>0,'Boletins Nuppa Site'!H5,"NULL") -> 30 | G5: =IF('Boletins Nuppa Site'!I5<>0,'Boletins Nuppa Site'!I5,"NULL") -> 24 | H5: =IF('Boletins Nuppa Site'!J5<>0,'Boletins Nuppa Site'!J5,"NULL") -> 24 | J5: ="INSERT INTO COTACAO (blt_id, pap_id, cot_prc_comum, cot_prc_min, cot_prc_max, cot_prc_med, cot_prc_mediana) VALUES ("&B5&", "&C5&", "&D5&", "&E5&", "&F5&", "&G5&", "&H5&");" -> INSERT INTO COTACAO (blt_id, pap_id, cot_prc_comum, cot_prc_min, cot_prc_max, cot_prc_med, cot_prc_mediana) VALUES (1, 4, NULL, 18, 30, 24, 24);
A6: 5 | B6: 1 | C6: 5 | D6: =IF('Boletins Nuppa Site'!F6<>0,'Boletins Nuppa Site'!F6,"NULL") -> NULL | E6: =IF('Boletins Nuppa Site'!G6<>0,'Boletins Nuppa Site'!G6,"NULL") -> 18 | F6: =IF('Boletins Nuppa Site'!H6<>0,'Boletins Nuppa Site'!H6,"NULL") -> 30 | G6: =IF('Boletins Nuppa Site'!I6<>0,'Boletins Nuppa Site'!I6,"NULL") -> 24 | H6: =IF('Boletins Nuppa Site'!J6<>0,'Boletins Nuppa Site'!J6,"NULL") -> 24 | J6: ="INSERT INTO COTACAO (blt_id, pap_id, cot_prc_comum, cot_prc_min, cot_prc_max, cot_prc_med, cot_prc_mediana) VALUES ("&B6&", "&C6&", "&D6&", "&E6&", "&F6&", "&G6&", "&H6&");" -> INSERT INTO COTACAO (blt_id, pap_id, cot_prc_comum, cot_prc_min, cot_prc_max, cot_prc_med, cot_prc_mediana) VALUES (1, 5, NULL, 18, 30, 24, 24);
A7: 6 | B7: 1 | C7: 6 | D7: =IF('Boletins Nuppa Site'!F7<>0,'Boletins Nuppa Site'!F7,"NULL") -> NULL | E7: =IF('Boletins Nuppa Site'!G7<>0,'Boletins Nuppa Site'!G7,"NULL") -> 48 | F7: =IF('Boletins Nuppa Site'!H7<>0,'Boletins Nuppa Site'!H7,"NULL") -> 48 | G7: =IF('Boletins Nuppa Site'!I7<>0,'Boletins Nuppa Site'!I7,"NULL") -> 48 | H7: =IF('Boletins Nuppa Site'!J7<>0,'Boletins Nuppa Site'!J7,"NULL") -> 48 | J7: ="INSERT INTO COTACAO (blt_id, pap_id, cot_prc_comum, cot_prc_min, cot_prc_max, cot_prc_med, cot_prc_mediana) VALUES ("&B7&", "&C7&", "&D7&", "&E7&", "&F7&", "&G7&", "&H7&");" -> INSERT INTO COTACAO (blt_id, pap_id, cot_prc_comum, cot_prc_min, cot_prc_max, cot_prc_med, cot_prc_mediana) VALUES (1, 6, NULL, 48, 48, 48, 48);
A8: 7 | B8: 1 | C8: 7 | D8: =IF('Boletins Nuppa Site'!F8<>0,'Boletins Nuppa Site'!F8,"NULL") -> NULL | E8: =IF('Boletins Nuppa Site'!G8<>0,'Boletins Nuppa Site'!G8,"NULL") -> 60 | F8: =IF('Boletins Nuppa Site'!H8<>0,'Boletins Nuppa Site'!H8,"NULL") -> 60 | G8: =IF('Boletins Nuppa Site'!I8<>0,'Boletins Nuppa Site'!I8,"NULL") -> 60 | H8: =IF('Boletins Nuppa Site'!J8<>0,'Boletins Nuppa Site'!J8,"NULL") -> 60 | J8: ="INSERT INTO COTACAO (blt_id, pap_id, cot_prc_comum, cot_prc_min, cot_prc_max, cot_prc_med, cot_prc_mediana) VALUES ("&B8&", "&C8&", "&D8&", "&E8&", "&F8&", "&G8&", "&H8&");" -> INSERT INTO COTACAO (blt_id, pap_id, cot_prc_comum, cot_prc_min, cot_prc_max, cot_prc_med, cot_prc_mediana) VALUES (1, 7, NULL, 60, 60, 60, 60);
A9: 8 | B9: 1 | C9: 8 | D9: =IF('Boletins Nuppa Site'!F9<>0,'Boletins Nuppa Site'!F9,"NULL") -> 48 | E9: =IF('Boletins Nuppa Site'!G9<>0,'Boletins Nuppa Site'!G9,"NULL") -> 48 | F9: =IF('Boletins Nuppa Site'!H9<>0,'Boletins Nuppa Site'!H9,"NULL") -> 60 | G9: =IF('Boletins Nuppa Site'!I9<>0,'Boletins Nuppa Site'!I9,"NULL") -> 52 | H9: =IF('Boletins Nuppa Site'!J9<>0,'Boletins Nuppa Site'!J9,"NULL") -> 48 | J9: ="INSERT INTO COTACAO (blt_id, pap_id, cot_prc_comum, cot_prc_min, cot_prc_max, cot_prc_med, cot_prc_mediana) VALUES ("&B9&", "&C9&", "&D9&", "&E9&", "&F9&", "&G9&", "&H9&");" -> INSERT INTO COTACAO (blt_id, pap_id, cot_prc_comum, cot_prc_min, cot_prc_max, cot_prc_med, cot_prc_mediana) VALUES (1, 8, 48, 48, 60, 52, 48);
A10: 9 | B10: 1 | C10: 9 | D10: =IF('Boletins Nuppa Site'!F10<>0,'Boletins Nuppa Site'!F10,"NULL") -> 15 | E10: =IF('Boletins Nuppa Site'!G10<>0,'Boletins Nuppa Site'!G10,"NULL") -> 15 | F10: =IF('Boletins Nuppa Site'!H10<>0,'Boletins Nuppa Site'!H10,"NULL") -> 24 | G10: =IF('Boletins Nuppa Site'!I10<>0,'Boletins Nuppa Site'!I10,"NULL") -> 18 | H10: =IF('Boletins Nuppa Site'!J10<>0,'Boletins Nuppa Site'!J10,"NULL") -> 15 | J10: ="INSERT INTO COTACAO (blt_id, pap_id, cot_prc_comum, cot_prc_min, cot_prc_max, cot_prc_med, cot_prc_mediana) VALUES ("&B10&", "&C10&", "&D10&", "&E10&", "&F10&", "&G10&", "&H10&");" -> INSERT INTO COTACAO (blt_id, pap_id, cot_prc_comum, cot_prc_min, cot_prc_max, cot_prc_med, cot_prc_mediana) VALUES (1, 9, 15, 15, 24, 18, 15);
A11: 10 | B11: 1 | C11: 10 | D11: =IF('Boletins Nuppa Site'!F11<>0,'Boletins Nuppa Site'!F11,"NULL") -> NULL | E11: =IF('Boletins Nuppa Site'!G11<>0,'Boletins Nuppa Site'!G11,"NULL") -> 60 | F11: =IF('Boletins Nuppa Site'!H11<>0,'Boletins Nuppa Site'!H11,"NULL") -> 60 | G11: =IF('Boletins Nuppa Site'!I11<>0,'Boletins Nuppa Site'!I11,"NULL") -> 60 | H11: =IF('Boletins Nuppa Site'!J11<>0,'Boletins Nuppa Site'!J11,"NULL") -> 60 | J11: ="INSERT INTO COTACAO (blt_id, pap_id, cot_prc_comum, cot_prc_min, cot_prc_max, cot_prc_med, cot_prc_mediana) VALUES ("&B11&", "&C11&", "&D11&", "&E11&", "&F11&", "&G11&", "&H11&");" -> INSERT INTO COTACAO (blt_id, pap_id, cot_prc_comum, cot_prc_min, cot_prc_max, cot_prc_med, cot_prc_mediana) VALUES (1, 10, NULL, 60, 60, 60, 60);
A12: 11 | B12: 1 | C12: 11 | D12: =IF('Boletins Nuppa Site'!F12<>0,'Boletins Nuppa Site'!F12,"NULL") -> NULL | E12: =IF('Boletins Nuppa Site'!G12<>0,'Boletins Nuppa Site'!G12,"NULL") -> 18 | F12: =IF('Boletins Nuppa Site'!H12<>0,'Boletins Nuppa Site'!H12,"NULL") -> 30 | G12: =IF('Boletins Nuppa Site'!I12<>0,'Boletins Nuppa Site'!I12,"NULL") -> 24 | H12: =IF('Boletins Nuppa Site'!J12<>0,'Boletins Nuppa Site'!J12,"NULL") -> 24 | J12: ="INSERT INTO COTACAO (blt_id, pap_id, cot_prc_comum, cot_prc_min, cot_prc_max, cot_prc_med, cot_prc_mediana) VALUES ("&B12&", "&C12&", "&D12&", "&E12&", "&F12&", "&G12&", "&H12&");" -> INSERT INTO COTACAO (blt_id, pap_id, cot_prc_comum, cot_prc_min, cot_prc_max, cot_prc_med, cot_prc_mediana) VALUES (1, 11, NULL, 18, 30, 24, 24);
A13: 12 | B13: 1 | C13: 12 | D13: =IF('Boletins Nuppa Site'!F13<>0,'Boletins Nuppa Site'!F13,"NULL") -> NULL | E13: =IF('Boletins Nuppa Site'!G13<>0,'Boletins Nuppa Site'!G13,"NULL") -> 42 | F13: =IF('Boletins Nuppa Site'!H13<>0,'Boletins Nuppa Site'!H13,"NULL") -> 54 | G13: =IF('Boletins Nuppa Site'!I13<>0,'Boletins Nuppa Site'!I13,"NULL") -> 48 | H13: =IF('Boletins Nuppa Site'!J13<>0,'Boletins Nuppa Site'!J13,"NULL") -> 48 | J13: ="INSERT INTO COTACAO (blt_id, pap_id, cot_prc_comum, cot_prc_min, cot_prc_max, cot_prc_med, cot_prc_mediana) VALUES ("&B13&", "&C13&", "&D13&", "&E13&", "&F13&", "&G13&", "&H13&");" -> INSERT INTO COTACAO (blt_id, pap_id, cot_prc_comum, cot_prc_min, cot_prc_max, cot_prc_med, cot_prc_mediana) VALUES (1, 12, NULL, 42, 54, 48, 48);
... A1430: 1429 | B1430: 37 | C1430: 39 | D1430: =IF('Boletins Nuppa Site'!F1430<>0,'Boletins Nuppa Site'!F1430,"NULL") -> NULL | E1430: =IF('Boletins Nuppa Site'!G1430<>0,'Boletins Nuppa Site'!G1430,"NULL") -> 70 | F1430: =IF('Boletins Nuppa Site'!H1430<>0,'Boletins Nuppa Site'!H1430,"NULL") -> 70 | G1430: =IF('Boletins Nuppa Site'!I1430<>0,'Boletins Nuppa Site'!I1430,"NULL") -> 70 | H1430: =IF('Boletins Nuppa Site'!J1430<>0,'Boletins Nuppa Site'!J1430,"NULL") -> 70 | J1430: ="INSERT INTO COTACAO (blt_id, pap_id, cot_prc_comum, cot_prc_min, cot_prc_max, cot_prc_med, cot_prc_mediana) VALUES ("&B1430&", "&C1430&", "&D1430&", "&E1430&", "&F1430&", "&G1430&", "&H1430&");" -> INSERT INTO COTACAO (blt_id, pap_id, cot_prc_comum, cot_prc_min, cot_prc_max, cot_prc_med, cot_prc_mediana) VALUES (37, 39, NULL, 70, 70, 70, 70);

Sheet completo
A1: blt_numero | B1: blt_ano | C1: blt_data | D1: grp_nome | E1: cat_nome | F1: prd_nome | G1: pap | H1: pap_qtd | I1: umd_nome | J1: cot_prc_comum | K1: cot_prc_min | L1: cot_prc_max | M1: cot_prc_med | N1: cot_prc_mediano

Sheet GRUPO_ALIMENTAR
A1: grp_id | B1: grp_nome | C1: grp_desc
A2: 1 | B2: A | C2: Verduras (folhosas, flores e hastes) | D2: ="INSERT INTO GRUPO_ALIMENTAR (grp_id, grp_nome, grp_desc) VALUES ("&A2&", '"&B2&"', '"&C2&"');" -> INSERT INTO GRUPO_ALIMENTAR (grp_id, grp_nome, grp_desc) VALUES (1, 'A', 'Verduras (folhosas, flores e hastes)'); | E2: INSERT INTO GRUPO_ALIMENTAR (grp_id, grp_nome, grp_desc) VALUES (1, 'A', 'Verduras (folhosas, flores e hastes)');
A3: 2 | B3: B | C3: Hortaliças condimentares (temperos) | D3: ="INSERT INTO GRUPO_ALIMENTAR (grp_id, grp_nome, grp_desc) VALUES ("&A3&", '"&B3&"', '"&C3&"');" -> INSERT INTO GRUPO_ALIMENTAR (grp_id, grp_nome, grp_desc) VALUES (2, 'B', 'Hortaliças condimentares (temperos)'); | E3: INSERT INTO GRUPO_ALIMENTAR (grp_id, grp_nome, grp_desc) VALUES (2, 'B', 'Hortaliças condimentares (temperos)');
A4: 3 | B4: C | C4: Hortaliças legumes (leguminosas (vagens), frutos, raízes tuberosas, tuberculos, bulbos) | D4: ="INSERT INTO GRUPO_ALIMENTAR (grp_id, grp_nome, grp_desc) VALUES ("&A4&", '"&B4&"', '"&C4&"');" -> INSERT INTO GRUPO_ALIMENTAR (grp_id, grp_nome, grp_desc) VALUES (3, 'C', 'Hortaliças legumes (leguminosas (vagens), frutos, raízes tuberosas, tuberculos, bulbos)'); | E4: INSERT INTO GRUPO_ALIMENTAR (grp_id, grp_nome, grp_desc) VALUES (3, 'C', 'Hortaliças legumes (leguminosas (vagens), frutos, raízes tuberosas, tuberculos, bulbos)');
A5: 4 | B5: D | C5: Frutas | D5: ="INSERT INTO GRUPO_ALIMENTAR (grp_id, grp_nome, grp_desc) VALUES ("&A5&", '"&B5&"', '"&C5&"');" -> INSERT INTO GRUPO_ALIMENTAR (grp_id, grp_nome, grp_desc) VALUES (4, 'D', 'Frutas'); | E5: INSERT INTO GRUPO_ALIMENTAR (grp_id, grp_nome, grp_desc) VALUES (4, 'D', 'Frutas');

Sheet CATEGORIA
A1: cat_id | B1: grp_id | C1: cat_nome
A2: 1 | B2: 1 | C2: Folhosas | E2: ="INSERT INTO CATEGORIA (grp_id, cat_nome) VALUES ("&B2&", '"&C2&"');" -> INSERT INTO CATEGORIA (grp_id, cat_nome) VALUES (1, 'Folhosas'); | F2: INSERT INTO CATEGORIA (grp_id, cat_nome) VALUES (1, 'Folhosas');
A3: 2 | B3: 1 | C3: Flores | E3: ="INSERT INTO CATEGORIA (grp_id, cat_nome) VALUES ("&B3&", '"&C3&"');" -> INSERT INTO CATEGORIA (grp_id, cat_nome) VALUES (1, 'Flores'); | F3: INSERT INTO CATEGORIA (grp_id, cat_nome) VALUES (1, 'Flores');
A4: 3 | B4: 1 | C4: Hastes | E4: ="INSERT INTO CATEGORIA (grp_id, cat_nome) VALUES ("&B4&", '"&C4&"');" -> INSERT INTO CATEGORIA (grp_id, cat_nome) VALUES (1, 'Hastes'); | F4: INSERT INTO CATEGORIA (grp_id, cat_nome) VALUES (1, 'Hastes');
A5: 4 | B5: 2 | C5: Temperos | E5: ="INSERT INTO CATEGORIA (grp_id, cat_nome) VALUES ("&B5&", '"&C5&"');" -> INSERT INTO CATEGORIA (grp_id, cat_nome) VALUES (2, 'Temperos'); | F5: INSERT INTO CATEGORIA (grp_id, cat_nome) VALUES (2, 'Temperos');
A6: 5 | B6: 3 | C6: Leguminosas (vagens) | E6: ="INSERT INTO CATEGORIA (grp_id, cat_nome) VALUES ("&B6&", '"&C6&"');" -> INSERT INTO CATEGORIA (grp_id, cat_nome) VALUES (3, 'Leguminosas (vagens)'); | F6: INSERT INTO CATEGORIA (grp_id, cat_nome) VALUES (3, 'Leguminosas (vagens)');
A7: 6 | B7: 3 | C7: Frutos | E7: ="INSERT INTO CATEGORIA (grp_id, cat_nome) VALUES ("&B7&", '"&C7&"');" -> INSERT INTO CATEGORIA (grp_id, cat_nome) VALUES (3, 'Frutos'); | F7: INSERT INTO CATEGORIA (grp_id, cat_nome) VALUES (3, 'Frutos');
A8: 7 | B8: 3 | C8: Raízes Tuberosas | E8: ="INSERT INTO CATEGORIA (grp_id, cat_nome) VALUES ("&B8&", '"&C8&"');" -> INSERT INTO CATEGORIA (grp_id, cat_nome) VALUES (3, 'Raízes Tuberosas'); | F8: INSERT INTO CATEGORIA (grp_id, cat_nome) VALUES (3, 'Raízes Tuberosas');
A9: 8 | B9: 3 | C9: Tubérculos | E9: ="INSERT INTO CATEGORIA (grp_id, cat_nome) VALUES ("&B9&", '"&C9&"');" -> INSERT INTO CATEGORIA (grp_id, cat_nome) VALUES (3, 'Tubérculos'); | F9: INSERT INTO CATEGORIA (grp_id, cat_nome) VALUES (3, 'Tubérculos');
A10: 9 | B10: 3 | C10: Bulbos | E10: ="INSERT INTO CATEGORIA (grp_id, cat_nome) VALUES ("&B10&", '"&C10&"');" -> INSERT INTO CATEGORIA (grp_id, cat_nome) VALUES (3, 'Bulbos'); | F10: INSERT INTO CATEGORIA (grp_id, cat_nome) VALUES (3, 'Bulbos');
A11: 10 | B11: 4 | C11: Frutas | E11: ="INSERT INTO CATEGORIA (grp_id, cat_nome) VALUES ("&B11&", '"&C11&"');" -> INSERT INTO CATEGORIA (grp_id, cat_nome) VALUES (4, 'Frutas'); | F11: INSERT INTO CATEGORIA (grp_id, cat_nome) VALUES (4, 'Frutas');

Sheet PRODUTO
A1: prd_id | B1: cat_id | C1: prd_nome | D1: prd_var | E1: prd_atv
A2: 1 | B2: 1 | C2: Acelga | E2: 1 | G2: ="INSERT INTO PRODUTO (cat_id, prd_nome, prd_var, prd_atv) VALUES ("&B2&", '"&C2&"', '"&D2&"', "&E2&");" -> INSERT INTO PRODUTO (cat_id, prd_nome, prd_var, prd_atv) VALUES (1, 'Acelga', '', 1); | H2: INSERT INTO PRODUTO (cat_id, prd_nome, prd_var, prd_atv) VALUES (1, 'Acelga', '', 1);
A3: 2 | B3: 1 | C3: Agrião | E3: 1 | G3: ="INSERT INTO PRODUTO (cat_id, prd_nome, prd_var, prd_atv) VALUES ("&B3&", '"&C3&"', '"&D3&"', "&E3&");" -> INSERT INTO PRODUTO (cat_id, prd_nome, prd_var, prd_atv) VALUES (1, 'Agrião', '', 1); | H3: INSERT INTO PRODUTO (cat_id, prd_nome, prd_var, prd_atv) VALUES (1, 'Agrião', '', 1);
A4: 3 | B4: 1 | C4: Alface | D4: Americana | E4: 1 | G4: ="INSERT INTO PRODUTO (cat_id, prd_nome, prd_var, prd_atv) VALUES ("&B4&", '"&C4&"', '"&D4&"', "&E4&");" -> INSERT INTO PRODUTO (cat_id, prd_nome, prd_var, prd_atv) VALUES (1, 'Alface', 'Americana', 1); | H4: INSERT INTO PRODUTO (cat_id, prd_nome, prd_var, prd_atv) VALUES (1, 'Alface', 'Americana', 1);
A5: 4 | B5: 1 | C5: Alface | D5: Crespa | E5: 1 | G5: ="INSERT INTO PRODUTO (cat_id, prd_nome, prd_var, prd_atv) VALUES ("&B5&", '"&C5&"', '"&D5&"', "&E5&");" -> INSERT INTO PRODUTO (cat_id, prd_nome, prd_var, prd_atv) VALUES (1, 'Alface', 'Crespa', 1); | H5: INSERT INTO PRODUTO (cat_id, prd_nome, prd_var, prd_atv) VALUES (1, 'Alface', 'Crespa', 1);
A6: 5 | B6: 1 | C6: Alface | D6: Lisa | E6: 1 | G6: ="INSERT INTO PRODUTO (cat_id, prd_nome, prd_var, prd_atv) VALUES ("&B6&", '"&C6&"', '"&D6&"', "&E6&");" -> INSERT INTO PRODUTO (cat_id, prd_nome, prd_var, prd_atv) VALUES (1, 'Alface', 'Lisa', 1); | H6: INSERT INTO PRODUTO (cat_id, prd_nome, prd_var, prd_atv) VALUES (1, 'Alface', 'Lisa', 1);
A7: 6 | B7: 1 | C7: Almeirão | E7: 1 | G7: ="INSERT INTO PRODUTO (cat_id, prd_nome, prd_var, prd_atv) VALUES ("&B7&", '"&C7&"', '"&D7&"', "&E7&");" -> INSERT INTO PRODUTO (cat_id, prd_nome, prd_var, prd_atv) VALUES (1, 'Almeirão', '', 1); | H7: INSERT INTO PRODUTO (cat_id, prd_nome, prd_var, prd_atv) VALUES (1, 'Almeirão', '', 1);
A8: 7 | B8: 2 | C8: Brócolis | D8: Ninja/Japonês | E8: 1 | G8: ="INSERT INTO PRODUTO (cat_id, prd_nome, prd_var, prd_atv) VALUES ("&B8&", '"&C8&"', '"&D8&"', "&E8&");" -> INSERT INTO PRODUTO (cat_id, prd_nome, prd_var, prd_atv) VALUES (2, 'Brócolis', 'Ninja/Japonês', 1); | H8: INSERT INTO PRODUTO (cat_id, prd_nome, prd_var, prd_atv) VALUES (2, 'Brócolis', 'Ninja/Japonês', 1);
A9: 8 | B9: 2 | C9: Brócolis | D9: Ramoso | E9: 1 | G9: ="INSERT INTO PRODUTO (cat_id, prd_nome, prd_var, prd_atv) VALUES ("&B9&", '"&C9&"', '"&D9&"', "&E9&");" -> INSERT INTO PRODUTO (cat_id, prd_nome, prd_var, prd_atv) VALUES (2, 'Brócolis', 'Ramoso', 1); | H9: INSERT INTO PRODUTO (cat_id, prd_nome, prd_var, prd_atv) VALUES (2, 'Brócolis', 'Ramoso', 1);
A10: 9 | B10: 1 | C10: Couve | D10: Manteiga | E10: 1 | G10: ="INSERT INTO PRODUTO (cat_id, prd_nome, prd_var, prd_atv) VALUES ("&B10&", '"&C10&"', '"&D10&"', "&E10&");" -> INSERT INTO PRODUTO (cat_id, prd_nome, prd_var, prd_atv) VALUES (1, 'Couve', 'Manteiga', 1); | H10: INSERT INTO PRODUTO (cat_id, prd_nome, prd_var, prd_atv) VALUES (1, 'Couve', 'Manteiga', 1);
A11: 10 | B11: 2 | C11: Couve-Flor | E11: 1 | G11: ="INSERT INTO PRODUTO (cat_id, prd_nome, prd_var, prd_atv) VALUES ("&B11&", '"&C11&"', '"&D11&"', "&E11&");" -> INSERT INTO PRODUTO (cat_id, prd_nome, prd_var, prd_atv) VALUES (2, 'Couve-Flor', '', 1); | H11: INSERT INTO PRODUTO (cat_id, prd_nome, prd_var, prd_atv) VALUES (2, 'Couve', '', 1);
A12: 11 | B12: 1 | C12: Escarola | E12: 1 | G12: ="INSERT INTO PRODUTO (cat_id, prd_nome, prd_var, prd_atv) VALUES ("&B12&", '"&C12&"', '"&D12&"', "&E12&");" -> INSERT INTO PRODUTO (cat_id, prd_nome, prd_var, prd_atv) VALUES (1, 'Escarola', '', 1); | H12: INSERT INTO PRODUTO (cat_id, prd_nome, prd_var, prd_atv) VALUES (1, 'Escarola', '', 1);
A13: 12 | B13: 1 | C13: Espinafre | E13: 1 | G13: ="INSERT INTO PRODUTO (cat_id, prd_nome, prd_var, prd_atv) VALUES ("&B13&", '"&C13&"', '"&D13&"', "&E13&");" -> INSERT INTO PRODUTO (cat_id, prd_nome, prd_var, prd_atv) VALUES (1, 'Espinafre', '', 1); | H13: INSERT INTO PRODUTO (cat_id, prd_nome, prd_var, prd_atv) VALUES (1, 'Espinafre', '', 1);
A14: 13 | B14: 7 | C14: Rabanete | E14: 1 | G14: ="INSERT INTO PRODUTO (cat_id, prd_nome, prd_var, prd_atv) VALUES ("&B14&", '"&C14&"', '"&D14&"', "&E14&");" -> INSERT INTO PRODUTO (cat_id, prd_nome, prd_var, prd_atv) VALUES (7, 'Rabanete', '', 1); | H14: INSERT INTO PRODUTO (cat_id, prd_nome, prd_var, prd_atv) VALUES (7, 'Rabanete', '', 1);
A15: 14 | B15: 1 | C15: Repolho | D15: Roxo | E15: 1 | G15: ="INSERT INTO PRODUTO (cat_id, prd_nome, prd_var, prd_atv) VALUES ("&B15&", '"&C15&"', '"&D15&"', "&E15&");" -> INSERT INTO PRODUTO (cat_id, prd_nome, prd_var, prd_atv) VALUES (1, 'Repolho', 'Roxo', 1); | H15: INSERT INTO PRODUTO (cat_id, prd_nome, prd_var, prd_atv) VALUES (1, 'Repolho', 'Roxo', 1);
A16: 15 | B16: 1 | C16: Repolho | D16: Verde | E16: 1 | G16: ="INSERT INTO PRODUTO (cat_id, prd_nome, prd_var, prd_atv) VALUES ("&B16&", '"&C16&"', '"&D16&"', "&E16&");" -> INSERT INTO PRODUTO (cat_id, prd_nome, prd_var, prd_atv) VALUES (1, 'Repolho', 'Verde', 1); | H16: INSERT INTO PRODUTO (cat_id, prd_nome, prd_var, prd_atv) VALUES (1, 'Repolho', 'Verde', 1);
A17: 16 | B17: 1 | C17: Rúcula | E17: 1 | G17: ="INSERT INTO PRODUTO (cat_id, prd_nome, prd_var, prd_atv) VALUES ("&B17&", '"&C17&"', '"&D17&"', "&E17&");" -> INSERT INTO PRODUTO (cat_id, prd_nome, prd_var, prd_atv) VALUES (1, 'Rúcula', '', 1); | H17: INSERT INTO PRODUTO (cat_id, prd_nome, prd_var, prd_atv) VALUES (1, 'Rúcula', '', 1);
A18: 17 | B18: 4 | C18: Cebolinha | E18: 1 | G18: ="INSERT INTO PRODUTO (cat_id, prd_nome, prd_var, prd_atv) VALUES ("&B18&", '"&C18&"', '"&D18&"', "&E18&");" -> INSERT INTO PRODUTO (cat_id, prd_nome, prd_var, prd_atv) VALUES (4, 'Cebolinha', '', 1); | H18: INSERT INTO PRODUTO (cat_id, prd_nome, prd_var, prd_atv) VALUES (4, 'Cebolinha', '', 1);
A19: 18 | B19: 4 | C19: Coentro | E19: 1 | G19: ="INSERT INTO PRODUTO (cat_id, prd_nome, prd_var, prd_atv) VALUES ("&B19&", '"&C19&"', '"&D19&"', "&E19&");" -> INSERT INTO PRODUTO (cat_id, prd_nome, prd_var, prd_atv) VALUES (4, 'Coentro', '', 1); | H19: INSERT INTO PRODUTO (cat_id, prd_nome, prd_var, prd_atv) VALUES (4, 'Coentro', '', 1);
A20: 19 | B20: 4 | C20: Salsinha | E20: 1 | G20: ="INSERT INTO PRODUTO (cat_id, prd_nome, prd_var, prd_atv) VALUES ("&B20&", '"&C20&"', '"&D20&"', "&E20&");" -> INSERT INTO PRODUTO (cat_id, prd_nome, prd_var, prd_atv) VALUES (4, 'Salsinha', '', 1); | H20: INSERT INTO PRODUTO (cat_id, prd_nome, prd_var, prd_atv) VALUES (4, 'Salsinha', '', 1);
A21: 20 | B21: 6 | C21: Abóbora | D21: Cabotiá | E21: 1 | G21: ="INSERT INTO PRODUTO (cat_id, prd_nome, prd_var, prd_atv) VALUES ("&B21&", '"&C21&"', '"&D21&"', "&E21&");" -> INSERT INTO PRODUTO (cat_id, prd_nome, prd_var, prd_atv) VALUES (6, 'Abóbora', 'Cabotiá', 1); | H21: INSERT INTO PRODUTO (cat_id, prd_nome, prd_var, prd_atv) VALUES (6, 'Abóbora', 'Cabotiá', 1);
A22: 21 | B22: 6 | C22: Abobrinha | D22: Italiana | E22: 1 | G22: ="INSERT INTO PRODUTO (cat_id, prd_nome, prd_var, prd_atv) VALUES ("&B22&", '"&C22&"', '"&D22&"', "&E22&");" -> INSERT INTO PRODUTO (cat_id, prd_nome, prd_var, prd_atv) VALUES (6, 'Abobrinha', 'Italiana', 1); | H22: INSERT INTO PRODUTO (cat_id, prd_nome, prd_var, prd_atv) VALUES (6, 'Abobrinha', 'Italiana', 1);
A23: 22 | B23: 7 | C23: Batata-doce | E23: 1 | G23: ="INSERT INTO PRODUTO (cat_id, prd_nome, prd_var, prd_atv) VALUES ("&B23&", '"&C23&"', '"&D23&"', "&E23&");" -> INSERT INTO PRODUTO (cat_id, prd_nome, prd_var, prd_atv) VALUES (7, 'Batata-doce', '', 1); | H23: INSERT INTO PRODUTO (cat_id, prd_nome, prd_var, prd_atv) VALUES (7, 'Batata-doce', '', 1);
A24: 23 | B24: 6 | C24: Berinjela | D24: Comum | E24: 1 | G24: ="INSERT INTO PRODUTO (cat_id, prd_nome, prd_var, prd_atv) VALUES ("&B24&", '"&C24&"', '"&D24&"', "&E24&");" -> INSERT INTO PRODUTO (cat_id, prd_nome, prd_var, prd_atv) VALUES (6, 'Berinjela', 'Comum', 1); | H24: INSERT INTO PRODUTO (cat_id, prd_nome, prd_var, prd_atv) VALUES (6, 'Berinjela', 'Comum', 1);
A25: 24 | B25: 6 | C25: Berinjela | D25: Japonesa | E25: 1 | G25: ="INSERT INTO PRODUTO (cat_id, prd_nome, prd_var, prd_atv) VALUES ("&B25&", '"&C25&"', '"&D25&"', "&E25&");" -> INSERT INTO PRODUTO (cat_id, prd_nome, prd_var, prd_atv) VALUES (6, 'Berinjela', 'Japonesa', 1); | H25: INSERT INTO PRODUTO (cat_id, prd_nome, prd_var, prd_atv) VALUES (6, 'Berinjela', 'Japonesa', 1);
A26: 25 | B26: 7 | C26: Beterraba | E26: 1 | G26: ="INSERT INTO PRODUTO (cat_id, prd_nome, prd_var, prd_atv) VALUES ("&B26&", '"&C26&"', '"&D26&"', "&E26&");" -> INSERT INTO PRODUTO (cat_id, prd_nome, prd_var, prd_atv) VALUES (7, 'Beterraba', '', 1); | H26: INSERT INTO PRODUTO (cat_id, prd_nome, prd_var, prd_atv) VALUES (7, 'Beterraba', '', 1);
A27: 26 | B27: 7 | C27: Cenoura | E27: 1 | G27: ="INSERT INTO PRODUTO (cat_id, prd_nome, prd_var, prd_atv) VALUES ("&B27&", '"&C27&"', '"&D27&"', "&E27&");" -> INSERT INTO PRODUTO (cat_id, prd_nome, prd_var, prd_atv) VALUES (7, 'Cenoura', '', 1); | H27: INSERT INTO PRODUTO (cat_id, prd_nome, prd_var, prd_atv) VALUES (7, 'Cenoura', '', 1);
A28: 27 | B28: 6 | C28: Chuchu | E28: 1 | G28: ="INSERT INTO PRODUTO (cat_id, prd_nome, prd_var, prd_atv) VALUES ("&B28&", '"&C28&"', '"&D28&"', "&E28&");" -> INSERT INTO PRODUTO (cat_id, prd_nome, prd_var, prd_atv) VALUES (6, 'Chuchu', '', 1); | H28: INSERT INTO PRODUTO (cat_id, prd_nome, prd_var, prd_atv) VALUES (6, 'Chuchu', '', 1);
A29: 28 | B29: 6 | C29: Jiló | E29: 1 | G29: ="INSERT INTO PRODUTO (cat_id, prd_nome, prd_var, prd_atv) VALUES ("&B29&", '"&C29&"', '"&D29&"', "&E29&");" -> INSERT INTO PRODUTO (cat_id, prd_nome, prd_var, prd_atv) VALUES (6, 'Jiló', '', 1); | H29: INSERT INTO PRODUTO (cat_id, prd_nome, prd_var, prd_atv) VALUES (6, 'Jiló', '', 1);
A30: 29 | B30: 7 | C30: Mandioca | E30: 1 | G30: ="INSERT INTO PRODUTO (cat_id, prd_nome, prd_var, prd_atv) VALUES ("&B30&", '"&C30&"', '"&D30&"', "&E30&");" -> INSERT INTO PRODUTO (cat_id, prd_nome, prd_var, prd_atv) VALUES (7, 'Mandioca', '', 1); | H30: INSERT INTO PRODUTO (cat_id, prd_nome, prd_var, prd_atv) VALUES (7, 'Mandioca', '', 1);
A31: 30 | B31: 6 | C31: Pepino | D31: Comum | E31: 1 | G31: ="INSERT INTO PRODUTO (cat_id, prd_nome, prd_var, prd_atv) VALUES ("&B31&", '"&C31&"', '"&D31&"', "&E31&");" -> INSERT INTO PRODUTO (cat_id, prd_nome, prd_var, prd_atv) VALUES (6, 'Pepino', 'Comum', 1); | H31: INSERT INTO PRODUTO (cat_id, prd_nome, prd_var, prd_atv) VALUES (6, 'Pepino', 'Comum', 1);
A32: 31 | B32: 6 | C32: Pepino | D32: Japonês | E32: 1 | G32: ="INSERT INTO PRODUTO (cat_id, prd_nome, prd_var, prd_atv) VALUES ("&B32&", '"&C32&"', '"&D32&"', "&E32&");" -> INSERT INTO PRODUTO (cat_id, prd_nome, prd_var, prd_atv) VALUES (6, 'Pepino', 'Japonês', 1); | H32: INSERT INTO PRODUTO (cat_id, prd_nome, prd_var, prd_atv) VALUES (6, 'Pepino', 'Japonês', 1);
A33: 32 | B33: 6 | C33: Pimentão | D33: Verde | E33: 1 | G33: ="INSERT INTO PRODUTO (cat_id, prd_nome, prd_var, prd_atv) VALUES ("&B33&", '"&C33&"', '"&D33&"', "&E33&");" -> INSERT INTO PRODUTO (cat_id, prd_nome, prd_var, prd_atv) VALUES (6, 'Pimentão', 'Verde', 1); | H33: INSERT INTO PRODUTO (cat_id, prd_nome, prd_var, prd_atv) VALUES (6, 'Pimentão', 'Verde', 1);
A34: 33 | B34: 6 | C34: Quiabo | E34: 1 | G34: ="INSERT INTO PRODUTO (cat_id, prd_nome, prd_var, prd_atv) VALUES ("&B34&", '"&C34&"', '"&D34&"', "&E34&");" -> INSERT INTO PRODUTO (cat_id, prd_nome, prd_var, prd_atv) VALUES (6, 'Quiabo', '', 1); | H34: INSERT INTO PRODUTO (cat_id, prd_nome, prd_var, prd_atv) VALUES (6, 'Quiabo', '', 1);
A35: 34 | B35: 6 | C35: Tomate | D35: Débora | E35: 1 | G35: ="INSERT INTO PRODUTO (cat_id, prd_nome, prd_var, prd_atv) VALUES ("&B35&", '"&C35&"', '"&D35&"', "&E35&");" -> INSERT INTO PRODUTO (cat_id, prd_nome, prd_var, prd_atv) VALUES (6, 'Tomate', 'Débora', 1); | H35: INSERT INTO PRODUTO (cat_id, prd_nome, prd_var, prd_atv) VALUES (6, 'Tomate', 'Débora', 1);
A36: 35 | B36: 5 | C36: Vagem | D36: Macarrão | E36: 1 | G36: ="INSERT INTO PRODUTO (cat_id, prd_nome, prd_var, prd_atv) VALUES ("&B36&", '"&C36&"', '"&D36&"', "&E36&");" -> INSERT INTO PRODUTO (cat_id, prd_nome, prd_var, prd_atv) VALUES (5, 'Vagem', 'Macarrão', 1); | H36: INSERT INTO PRODUTO (cat_id, prd_nome, prd_var, prd_atv) VALUES (5, 'Vagem', 'Macarrão', 1);
A37: 36 | B37: 10 | C37: Caqui | D37: Fuyu | E37: 1 | G37: ="INSERT INTO PRODUTO (cat_id, prd_nome, prd_var, prd_atv) VALUES ("&B37&", '"&C37&"', '"&D37&"', "&E37&");" -> INSERT INTO PRODUTO (cat_id, prd_nome, prd_var, prd_atv) VALUES (10, 'Caqui', 'Fuyu', 1); | H37: INSERT INTO PRODUTO (cat_id, prd_nome, prd_var, prd_atv) VALUES (10, 'Caqui', 'Fuyu', 1);
A38: 37 | B38: 10 | C38: Caqui | D38: Guiombo | E38: 1 | G38: ="INSERT INTO PRODUTO (cat_id, prd_nome, prd_var, prd_atv) VALUES ("&B38&", '"&C38&"', '"&D38&"', "&E38&");" -> INSERT INTO PRODUTO (cat_id, prd_nome, prd_var, prd_atv) VALUES (10, 'Caqui', 'Guiombo', 1); | H38: INSERT INTO PRODUTO (cat_id, prd_nome, prd_var, prd_atv) VALUES (10, 'Caqui', 'Guiombo', 1);
A39: 38 | B39: 10 | C39: Caqui | D39: Rama Forte | E39: 1 | G39: ="INSERT INTO PRODUTO (cat_id, prd_nome, prd_var, prd_atv) VALUES ("&B39&", '"&C39&"', '"&D39&"', "&E39&");" -> INSERT INTO PRODUTO (cat_id, prd_nome, prd_var, prd_atv) VALUES (10, 'Caqui', 'Rama Forte', 1); | H39: INSERT INTO PRODUTO (cat_id, prd_nome, prd_var, prd_atv) VALUES (10, 'Caqui', 'Rama Forte', 1);
A40: 39 | B40: 10 | C40: Goiaba | E40: 1 | G40: ="INSERT INTO PRODUTO (cat_id, prd_nome, prd_var, prd_atv) VALUES ("&B40&", '"&C40&"', '"&D40&"', "&E40&");" -> INSERT INTO PRODUTO (cat_id, prd_nome, prd_var, prd_atv) VALUES (10, 'Goiaba', '', 1); | H40: INSERT INTO PRODUTO (cat_id, prd_nome, prd_var, prd_atv) VALUES (10, 'Goiaba', '', 1);
...

Sheet UNIDADE_MEDIDA
A1: umd_id | B1: umd_nome | C1: umd_sigla
A2: 1 | B2: Quilograma | C2: kg | E2: ="INSERT INTO UNIDADE_MEDIDA (umd_nome, umd_sigla) VALUES ('"&B2&"', '"&C2&"');" -> INSERT INTO UNIDADE_MEDIDA (umd_nome, umd_sigla) VALUES ('Quilograma', 'kg'); | F2: INSERT INTO UNIDADE_MEDIDA (umd_nome, umd_sigla) VALUES ('Quilograma', 'kg');
A3: 2 | B3: Grama | C3: g | E3: ="INSERT INTO UNIDADE_MEDIDA (umd_nome, umd_sigla) VALUES ('"&B3&"', '"&C3&"');" -> INSERT INTO UNIDADE_MEDIDA (umd_nome, umd_sigla) VALUES ('Grama', 'g'); | F3: INSERT INTO UNIDADE_MEDIDA (umd_nome, umd_sigla) VALUES ('Grama', 'g');
A4: 3 | B4: Unidade | C4: un | E4: ="INSERT INTO UNIDADE_MEDIDA (umd_nome, umd_sigla) VALUES ('"&B4&"', '"&C4&"');" -> INSERT INTO UNIDADE_MEDIDA (umd_nome, umd_sigla) VALUES ('Unidade', 'un'); | F4: INSERT INTO UNIDADE_MEDIDA (umd_nome, umd_sigla) VALUES ('Unidade', 'un');
A5: 4 | B5: Mililitro | C5: ml | E5: ="INSERT INTO UNIDADE_MEDIDA (umd_nome, umd_sigla) VALUES ('"&B5&"', '"&C5&"');" -> INSERT INTO UNIDADE_MEDIDA (umd_nome, umd_sigla) VALUES ('Mililitro', 'ml'); | F5: INSERT INTO UNIDADE_MEDIDA (umd_nome, umd_sigla) VALUES ('Mililitro', 'ml');
A6: 5 | B6: Litro | C6: L | E6: ="INSERT INTO UNIDADE_MEDIDA (umd_nome, umd_sigla) VALUES ('"&B6&"', '"&C6&"');" -> INSERT INTO UNIDADE_MEDIDA (umd_nome, umd_sigla) VALUES ('Litro', 'L'); | F6: INSERT INTO UNIDADE_MEDIDA (umd_nome, umd_sigla) VALUES ('Litro', 'L');

Sheet TIPO_APRESENTACAO
A1: tap_id | B1: tap_nome
A2: 1 | B2: caixa | E2: ="INSERT INTO TIPO_APRESENTACAO (tap_nome) VALUES ('"&B2&"');" -> INSERT INTO TIPO_APRESENTACAO (tap_nome) VALUES ('caixa');
A3: 2 | B3: maço | E3: ="INSERT INTO TIPO_APRESENTACAO (tap_nome) VALUES ('"&B3&"');" -> INSERT INTO TIPO_APRESENTACAO (tap_nome) VALUES ('maço');
A4: 3 | B4: dúzia | E4: ="INSERT INTO TIPO_APRESENTACAO (tap_nome) VALUES ('"&B4&"');" -> INSERT INTO TIPO_APRESENTACAO (tap_nome) VALUES ('dúzia');
A5: 4 | B5: saco | E5: ="INSERT INTO TIPO_APRESENTACAO (tap_nome) VALUES ('"&B5&"');" -> INSERT INTO TIPO_APRESENTACAO (tap_nome) VALUES ('saco');

Sheet BOLETIM
A1: blt_id | B1: blt_numero | C1: blt_ano | D1: blt_data_lev | E1: blt_data_cad
A2: 1 | B2: 37 | C2: 2023 | D2: 44931 | G2: ="INSERT INTO BOLETIM (blt_numero, blt_ano, blt_data_lev, blt_data_cad) VALUES ("&B2&", "&C2&", TO_DATE('"&TEXT(D2,"DD/MM/AAAA")&"', 'DD/MM/YYYY'), SYSDATE);" -> INSERT INTO BOLETIM (blt_numero, blt_ano, blt_data_lev, blt_data_cad) VALUES (37, 2023, TO_DATE('05/01/2023', 'DD/MM/YYYY'), SYSDATE);
A3: 2 | B3: 38 | C3: 2023 | D3: 44938 | G3: ="INSERT INTO BOLETIM (blt_numero, blt_ano, blt_data_lev, blt_data_cad) VALUES ("&B3&", "&C3&", TO_DATE('"&TEXT(D3,"DD/MM/AAAA")&"', 'DD/MM/YYYY'), SYSDATE);" -> INSERT INTO BOLETIM (blt_numero, blt_ano, blt_data_lev, blt_data_cad) VALUES (38, 2023, TO_DATE('12/01/2023', 'DD/MM/YYYY'), SYSDATE);
A4: 3 | B4: 39 | C4: 2023 | D4: 44945 | G4: ="INSERT INTO BOLETIM (blt_numero, blt_ano, blt_data_lev, blt_data_cad) VALUES ("&B4&", "&C4&", TO_DATE('"&TEXT(D4,"DD/MM/AAAA")&"', 'DD/MM/YYYY'), SYSDATE);" -> INSERT INTO BOLETIM (blt_numero, blt_ano, blt_data_lev, blt_data_cad) VALUES (39, 2023, TO_DATE('19/01/2023', 'DD/MM/YYYY'), SYSDATE);
A5: 4 | B5: 40 | C5: 2023 | D5: 44952 | G5: ="INSERT INTO BOLETIM (blt_numero, blt_ano, blt_data_lev, blt_data_cad) VALUES ("&B5&", "&C5&", TO_DATE('"&TEXT(D5,"DD/MM/AAAA")&"', 'DD/MM/YYYY'), SYSDATE);" -> INSERT INTO BOLETIM (blt_numero, blt_ano, blt_data_lev, blt_data_cad) VALUES (40, 2023, TO_DATE('26/01/2023', 'DD/MM/YYYY'), SYSDATE);
A6: 5 | B6: 41 | C6: 2023 | D6: 44959 | G6: ="INSERT INTO BOLETIM (blt_numero, blt_ano, blt_data_lev, blt_data_cad) VALUES ("&B6&", "&C6&", TO_DATE('"&TEXT(D6,"DD/MM/AAAA")&"', 'DD/MM/YYYY'), SYSDATE);" -> INSERT INTO BOLETIM (blt_numero, blt_ano, blt_data_lev, blt_data_cad) VALUES (41, 2023, TO_DATE('02/02/2023', 'DD/MM/YYYY'), SYSDATE);
A7: 6 | B7: 42 | C7: 2023 | D7: 44966 | G7: ="INSERT INTO BOLETIM (blt_numero, blt_ano, blt_data_lev, blt_data_cad) VALUES ("&B7&", "&C7&", TO_DATE('"&TEXT(D7,"DD/MM/AAAA")&"', 'DD/MM/YYYY'), SYSDATE);" -> INSERT INTO BOLETIM (blt_numero, blt_ano, blt_data_lev, blt_data_cad) VALUES (42, 2023, TO_DATE('09/02/2023', 'DD/MM/YYYY'), SYSDATE);
A8: 7 | B8: 43 | C8: 2023 | D8: 44973 | G8: ="INSERT INTO BOLETIM (blt_numero, blt_ano, blt_data_lev, blt_data_cad) VALUES ("&B8&", "&C8&", TO_DATE('"&TEXT(D8,"DD/MM/AAAA")&"', 'DD/MM/YYYY'), SYSDATE);" -> INSERT INTO BOLETIM (blt_numero, blt_ano, blt_data_lev, blt_data_cad) VALUES (43, 2023, TO_DATE('16/02/2023', 'DD/MM/YYYY'), SYSDATE);
A9: 8 | B9: 44 | C9: 2024 | D9: 45357 | G9: ="INSERT INTO BOLETIM (blt_numero, blt_ano, blt_data_lev, blt_data_cad) VALUES ("&B9&", "&C9&", TO_DATE('"&TEXT(D9,"DD/MM/AAAA")&"', 'DD/MM/YYYY'), SYSDATE);" -> INSERT INTO BOLETIM (blt_numero, blt_ano, blt_data_lev, blt_data_cad) VALUES (44, 2024, TO_DATE('06/03/2024', 'DD/MM/YYYY'), SYSDATE);
A10: 9 | B10: 45 | C10: 2024 | D10: 45364 | G10: ="INSERT INTO BOLETIM (blt_numero, blt_ano, blt_data_lev, blt_data_cad) VALUES ("&B10&", "&C10&", TO_DATE('"&TEXT(D10,"DD/MM/AAAA")&"', 'DD/MM/YYYY'), SYSDATE);" -> INSERT INTO BOLETIM (blt_numero, blt_ano, blt_data_lev, blt_data_cad) VALUES (45, 2024, TO_DATE('13/03/2024', 'DD/MM/YYYY'), SYSDATE);
A11: 10 | B11: 46 | C11: 2024 | D11: 45371 | G11: ="INSERT INTO BOLETIM (blt_numero, blt_ano, blt_data_lev, blt_data_cad) VALUES ("&B11&", "&C11&", TO_DATE('"&TEXT(D11,"DD/MM/AAAA")&"', 'DD/MM/YYYY'), SYSDATE);" -> INSERT INTO BOLETIM (blt_numero, blt_ano, blt_data_lev, blt_data_cad) VALUES (46, 2024, TO_DATE('20/03/2024', 'DD/MM/YYYY'), SYSDATE);
A12: 11 | B12: 47 | C12: 2024 | D12: 45385 | G12: ="INSERT INTO BOLETIM (blt_numero, blt_ano, blt_data_lev, blt_data_cad) VALUES ("&B12&", "&C12&", TO_DATE('"&TEXT(D12,"DD/MM/AAAA")&"', 'DD/MM/YYYY'), SYSDATE);" -> INSERT INTO BOLETIM (blt_numero, blt_ano, blt_data_lev, blt_data_cad) VALUES (47, 2024, TO_DATE('03/04/2024', 'DD/MM/YYYY'), SYSDATE);
A13: 12 | B13: 48 | C13: 2024 | D13: 45392 | G13: ="INSERT INTO BOLETIM (blt_numero, blt_ano, blt_data_lev, blt_data_cad) VALUES ("&B13&", "&C13&", TO_DATE('"&TEXT(D13,"DD/MM/AAAA")&"', 'DD/MM/YYYY'), SYSDATE);" -> INSERT INTO BOLETIM (blt_numero, blt_ano, blt_data_lev, blt_data_cad) VALUES (48, 2024, TO_DATE('10/04/2024', 'DD/MM/YYYY'), SYSDATE);
... A45: 44 | B45: 80 | C45: 2024 | D45: 45625 | G45: ="INSERT INTO BOLETIM (blt_numero, blt_ano, blt_data_lev, blt_data_cad) VALUES ("&B45&", "&C45&", TO_DATE('"&TEXT(D45,"DD/MM/AAAA")&"', 'DD/MM/YYYY'), SYSDATE);" -> INSERT INTO BOLETIM (blt_numero, blt_ano, blt_data_lev, blt_data_cad) VALUES (80, 2024, TO_DATE('29/11/2024', 'DD/MM/YYYY'), SYSDATE);

Sheet PRODUTO_APRESENTACAO
A1: pap_id | B1: prd_id | C1: tap_id | D1: pap_qtd | E1: umd_id | F1: pap_atv
A2: 1 | B2: 1 | C2: 3 | D2: 1 | F2: 1 | H2: ="INSERT INTO PRODUTO_APRESENTACAO (prd_id, tap_id, pap_qtd, umd_id, pap_atv) VALUES ("&B2&", "&C2&", "&D2&", "&E2&", "&F2&");" -> INSERT INTO PRODUTO_APRESENTACAO (prd_id, tap_id, pap_qtd, umd_id, pap_atv) VALUES (1, 3, 1, , 1);
A3: 2 | B3: 2 | C3: 3 | D3: 1 | F3: 1 | H3: ="INSERT INTO PRODUTO_APRESENTACAO (prd_id, tap_id, pap_qtd, umd_id, pap_atv) VALUES ("&B3&", "&C3&", "&D3&", "&E3&", "&F3&");" -> INSERT INTO PRODUTO_APRESENTACAO (prd_id, tap_id, pap_qtd, umd_id, pap_atv) VALUES (2, 3, 1, , 1);
A4: 3 | B4: 3 | C4: 3 | D4: 1 | F4: 1 | H4: ="INSERT INTO PRODUTO_APRESENTACAO (prd_id, tap_id, pap_qtd, umd_id, pap_atv) VALUES ("&B4&", "&C4&", "&D4&", "&E4&", "&F4&");" -> INSERT INTO PRODUTO_APRESENTACAO (prd_id, tap_id, pap_qtd, umd_id, pap_atv) VALUES (3, 3, 1, , 1);
A5: 4 | B5: 4 | C5: 3 | D5: 1 | F5: 1 | H5: ="INSERT INTO PRODUTO_APRESENTACAO (prd_id, tap_id, pap_qtd, umd_id, pap_atv) VALUES ("&B5&", "&C5&", "&D5&", "&E5&", "&F5&");" -> INSERT INTO PRODUTO_APRESENTACAO (prd_id, tap_id, pap_qtd, umd_id, pap_atv) VALUES (4, 3, 1, , 1);
A6: 5 | B6: 5 | C6: 3 | D6: 1 | F6: 1 | H6: ="INSERT INTO PRODUTO_APRESENTACAO (prd_id, tap_id, pap_qtd, umd_id, pap_atv) VALUES ("&B6&", "&C6&", "&D6&", "&E6&", "&F6&");" -> INSERT INTO PRODUTO_APRESENTACAO (prd_id, tap_id, pap_qtd, umd_id, pap_atv) VALUES (5, 3, 1, , 1);
A7: 6 | B7: 6 | C7: 3 | D7: 1 | F7: 1 | H7: ="INSERT INTO PRODUTO_APRESENTACAO (prd_id, tap_id, pap_qtd, umd_id, pap_atv) VALUES ("&B7&", "&C7&", "&D7&", "&E7&", "&F7&");" -> INSERT INTO PRODUTO_APRESENTACAO (prd_id, tap_id, pap_qtd, umd_id, pap_atv) VALUES (6, 3, 1, , 1);
A8: 7 | B8: 7 | C8: 3 | D8: 1 | F8: 1 | H8: ="INSERT INTO PRODUTO_APRESENTACAO (prd_id, tap_id, pap_qtd, umd_id, pap_atv) VALUES ("&B8&", "&C8&", "&D8&", "&E8&", "&F8&");" -> INSERT INTO PRODUTO_APRESENTACAO (prd_id, tap_id, pap_qtd, umd_id, pap_atv) VALUES (7, 3, 1, , 1);
A9: 8 | B9: 8 | C9: 3 | D9: 1 | F9: 1 | H9: ="INSERT INTO PRODUTO_APRESENTACAO (prd_id, tap_id, pap_qtd, umd_id, pap_atv) VALUES ("&B9&", "&C9&", "&D9&", "&E9&", "&F9&");" -> INSERT INTO PRODUTO_APRESENTACAO (prd_id, tap_id, pap_qtd, umd_id, pap_atv) VALUES (8, 3, 1, , 1);
A10: 9 | B10: 9 | C10: 3 | D10: 1 | F10: 1 | H10: ="INSERT INTO PRODUTO_APRESENTACAO (prd_id, tap_id, pap_qtd, umd_id, pap_atv) VALUES ("&B10&", "&C10&", "&D10&", "&E10&", "&F10&");" -> INSERT INTO PRODUTO_APRESENTACAO (prd_id, tap_id, pap_qtd, umd_id, pap_atv) VALUES (9, 3, 1, , 1);
A11: 10 | B11: 10 | C11: 3 | D11: 1 | F11: 1 | H11: ="INSERT INTO PRODUTO_APRESENTACAO (prd_id, tap_id, pap_qtd, umd_id, pap_atv) VALUES ("&B11&", "&C11&", "&D11&", "&E11&", "&F11&");" -> INSERT INTO PRODUTO_APRESENTACAO (prd_id, tap_id, pap_qtd, umd_id, pap_atv) VALUES (10, 3, 1, , 1);
A12: 11 | B12: 11 | C12: 3 | D12: 1 | F12: 1 | H12: ="INSERT INTO PRODUTO_APRESENTACAO (prd_id, tap_id, pap_qtd, umd_id, pap_atv) VALUES ("&B12&", "&C12&", "&D12&", "&E12&", "&F12&");" -> INSERT INTO PRODUTO_APRESENTACAO (prd_id, tap_id, pap_qtd, umd_id, pap_atv) VALUES (11, 3, 1, , 1);
A13: 12 | B13: 12 | C13: 3 | D13: 1 | F13: 1 | H13: ="INSERT INTO PRODUTO_APRESENTACAO (prd_id, tap_id, pap_qtd, umd_id, pap_atv) VALUES ("&B13&", "&C13&", "&D13&", "&E13&", "&F13&");" -> INSERT INTO PRODUTO_APRESENTACAO (prd_id, tap_id, pap_qtd, umd_id, pap_atv) VALUES (12, 3, 1, , 1);
... A17: 16 | B17: 16 | C17: 3 | D17: 1 | F17: 1 | H17: ="INSERT INTO PRODUTO_APRESENTACAO (prd_id, tap_id, pap_qtd, umd_id, pap_atv) VALUES ("&B17&", "&C17&", "&D17&", "&E17&", "&F17&");" -> INSERT INTO PRODUTO_APRESENTACAO (prd_id, tap_id, pap_qtd, umd_id, pap_atv) VALUES (16, 3, 1, , 1);
A18: 17 | B18: 17 | C18: 2 | D18: 0.5 | E18: 1 | F18: 1 | H18: ="INSERT INTO PRODUTO_APRESENTACAO (prd_id, tap_id, pap_qtd, umd_id, pap_atv) VALUES ("&B18&", "&C18&", "&D18&", "&E18&", "&F18&");" -> INSERT INTO PRODUTO_APRESENTACAO (prd_id, tap_id, pap_qtd, umd_id, pap_atv) VALUES (17, 2, 0,5, 1, 1);
A19: 18 | B19: 18 | C19: 2 | D19: 2 | E19: 1 | F19: 1 | H19: ="INSERT INTO PRODUTO_APRESENTACAO (prd_id, tap_id, pap_qtd, umd_id, pap_atv) VALUES ("&B19&", "&C19&", "&D19&", "&E19&", "&F19&");" -> INSERT INTO PRODUTO_APRESENTACAO (prd_id, tap_id, pap_qtd, umd_id, pap_atv) VALUES (18, 2, 2, 1, 1);
A20: 19 | B20: 19 | C20: 2 | D20: 2 | E20: 1 | F20: 1 | H20: ="INSERT INTO PRODUTO_APRESENTACAO (prd_id, tap_id, pap_qtd, umd_id, pap_atv) VALUES ("&B20&", "&C20&", "&D20&", "&E20&", "&F20&");" -> INSERT INTO PRODUTO_APRESENTACAO (prd_id, tap_id, pap_qtd, umd_id, pap_atv) VALUES (19, 2, 2, 1, 1);
A21: 20 | B21: 20 | C21: 1 | D21: 30 | E21: 1 | F21: 1 | H21: ="INSERT INTO PRODUTO_APRESENTACAO (prd_id, tap_id, pap_qtd, umd_id, pap_atv) VALUES ("&B21&", "&C21&", "&D21&", "&E21&", "&F21&");" -> INSERT INTO PRODUTO_APRESENTACAO (prd_id, tap_id, pap_qtd, umd_id, pap_atv) VALUES (20, 1, 30, 1, 1);
A22: 21 | B22: 21 | C22: 1 | D22: 17 | E22: 1 | F22: 1 | H22: ="INSERT INTO PRODUTO_APRESENTACAO (prd_id, tap_id, pap_qtd, umd_id, pap_atv) VALUES ("&B22&", "&C22&", "&D22&", "&E22&", "&F22&");" -> INSERT INTO PRODUTO_APRESENTACAO (prd_id, tap_id, pap_qtd, umd_id, pap_atv) VALUES (21, 1, 17, 1, 1);
A23: 22 | B23: 22 | C23: 1 | D23: 18 | E23: 1 | F23: 1 | H23: ="INSERT INTO PRODUTO_APRESENTACAO (prd_id, tap_id, pap_qtd, umd_id, pap_atv) VALUES ("&B23&", "&C23&", "&D23&", "&E23&", "&F23&");" -> INSERT INTO PRODUTO_APRESENTACAO (prd_id, tap_id, pap_qtd, umd_id, pap_atv) VALUES (22, 1, 18, 1, 1);
A24: 23 | B24: 23 | C24: 1 | D24: 10 | E24: 1 | F24: 1 | H24: ="INSERT INTO PRODUTO_APRESENTACAO (prd_id, tap_id, pap_qtd, umd_id, pap_atv) VALUES ("&B24&", "&C24&", "&D24&", "&E24&", "&F24&");" -> INSERT INTO PRODUTO_APRESENTACAO (prd_id, tap_id, pap_qtd, umd_id, pap_atv) VALUES (23, 1, 10, 1, 1);
A25: 24 | B25: 24 | C25: 1 | D25: 10 | E25: 1 | F25: 1 | H25: ="INSERT INTO PRODUTO_APRESENTACAO (prd_id, tap_id, pap_qtd, umd_id, pap_atv) VALUES ("&B25&", "&C25&", "&D25&", "&E25&", "&F25&");" -> INSERT INTO PRODUTO_APRESENTACAO (prd_id, tap_id, pap_qtd, umd_id, pap_atv) VALUES (24, 1, 10, 1, 1);
A26: 25 | B26: 25 | C26: 1 | D26: 20 | E26: 1 | F26: 1 | H26: ="INSERT INTO PRODUTO_APRESENTACAO (prd_id, tap_id, pap_qtd, umd_id, pap_atv) VALUES ("&B26&", "&C26&", "&D26&", "&E26&", "&F26&");" -> INSERT INTO PRODUTO_APRESENTACAO (prd_id, tap_id, pap_qtd, umd_id, pap_atv) VALUES (25, 1, 20, 1, 1);
A27: 26 | B27: 26 | C27: 1 | D27: 18 | E27: 1 | F27: 1 | H27: ="INSERT INTO PRODUTO_APRESENTACAO (prd_id, tap_id, pap_qtd, umd_id, pap_atv) VALUES ("&B27&", "&C27&", "&D27&", "&E27&", "&F27&");" -> INSERT INTO PRODUTO_APRESENTACAO (prd_id, tap_id, pap_qtd, umd_id, pap_atv) VALUES (26, 1, 18, 1, 1);
A28: 27 | B28: 27 | C28: 1 | D28: 18 | E28: 1 | F28: 1 | H28: ="INSERT INTO PRODUTO_APRESENTACAO (prd_id, tap_id, pap_qtd, umd_id, pap_atv) VALUES ("&B28&", "&C28&", "&D28&", "&E28&", "&F28&");" -> INSERT INTO PRODUTO_APRESENTACAO (prd_id, tap_id, pap_qtd, umd_id, pap_atv) VALUES (27, 1, 18, 1, 1);
A29: 28 | B29: 28 | C29: 1 | D29: 17 | E29: 1 | F29: 1 | H29: ="INSERT INTO PRODUTO_APRESENTACAO (prd_id, tap_id, pap_qtd, umd_id, pap_atv) VALUES ("&B29&", "&C29&", "&D29&", "&E29&", "&F29&");" -> INSERT INTO PRODUTO_APRESENTACAO (prd_id, tap_id, pap_qtd, umd_id, pap_atv) VALUES (28, 1, 17, 1, 1);
... A41: 40 | B41: 40 | C41: 1 | D41: 22 | E41: 1 | F41: 1 | H41: ="INSERT INTO PRODUTO_APRESENTACAO (prd_id, tap_id, pap_qtd, umd_id, pap_atv) VALUES ("&B41&", "&C41&", "&D41&", "&E41&", "&F41&");" -> INSERT INTO PRODUTO_APRESENTACAO (prd_id, tap_id, pap_qtd, umd_id, pap_atv) VALUES (40, 1, 22, 1, 1);
